Workbook
Name Balancetecontbilporperodo: 'PREVISTO 2026'!#REF!
Name Balancetecontbilporperodo: 'PREVISTO 2026 REVISADO'!#REF!
Name Balancetecontbilporperodo: 'PREVISTO 2026 REVISADO (2)'!#REF!
Name Balancetecontbilporperodo: 'REALIZADO 2025'!#REF!
Name JR_PAGE_ANCHOR_0_1: 'PREVISTO 2026'!#REF!
Name JR_PAGE_ANCHOR_0_1: 'PREVISTO 2026 REVISADO'!#REF!
Name JR_PAGE_ANCHOR_0_1: 'PREVISTO 2026 REVISADO (2)'!#REF!
Name JR_PAGE_ANCHOR_0_1: 'REALIZADO 2025'!#REF!

Sheet PREVISTO 2026 REVISADO
C1: Horiontal Praia Brava
C2: Previsão Orçamentária 2026
C3: Categorias | F3: Dezembro | G3: Janeiro | H3: Fevereiro | I3: Março | J3: Abril | K3: Maio | L3: Junho | M3: Julho | N3: Agosto | O3: Setembro | P3: Outubro | Q3: Novembro | R3: Total | S3: Média
C4: 2 Despesas | F4: =F5+F22+F38+F78+F86+#REF! -> #REF! | G4: =G5+G22+G38+G78+G86+#REF! -> #REF! | H4: =H5+H22+H38+H78+H86+#REF! -> #REF! | I4: =I5+I22+I38+I78+I86+#REF! -> #REF! | J4: =J5+J22+J38+J78+J86+#REF! -> #REF! | K4: =K5+K22+K38+K78+K86+#REF! -> #REF! | L4: =L5+L22+L38+L78+L86+#REF! -> #REF! | M4: =M5+M22+M38+M78+M86+#REF! -> #REF! | ... Q4: =Q5+Q22+Q38+Q78+Q86+#REF! -> #REF! | T4: REAJUSTE | U4: 1.045 | V4: 0.045
C5: 2.1 Administrativas | F5: =SUM(F6:F21) -> 9137.3607 | G5: =SUM(G6:G21) -> 8418.0037 | H5: =SUM(H6:H21) -> 83898.212 | I5: =SUM(I6:I21) -> 11787.819 | J5: =SUM(J6:J21) -> 9820.2203 | K5: =SUM(K6:K21) -> 11732.215 | L5: =SUM(L6:L21) -> 11683.814 | M5: =SUM(M6:M21) -> 10756.028 | ... R5: =SUM(R6:R21) -> 203286.84 | S5: =R5/12 -> 16940.57
C6: 2.1.1 Despesas Bancárias | F6: 34 | G6: 34 | H6: ='REALIZADO 2025'!F28*'PREVISTO 2026 REVISADO'!$U$4 -> 82.54455 | I6: ='REALIZADO 2025'!G28*'PREVISTO 2026 REVISADO'!$U$4 -> 62.06255 | J6: ='REALIZADO 2025'!H28*'PREVISTO 2026 REVISADO'!$U$4 -> 101.5949 | K6: ='REALIZADO 2025'!I28*'PREVISTO 2026 REVISADO'!$U$4 -> 39.6055 | L6: 35 | M6: ='REALIZADO 2025'!K28*'PREVISTO 2026 REVISADO'!$U$4 -> 33.3355 | N6: ='REALIZADO 2025'!L28*'PREVISTO 2026 REVISADO'!$U$4 -> 33.3355 | O6: ='REALIZADO 2025'!M28*'PREVISTO 2026 REVISADO'!$U$4 -> 34.3805 | P6: ='REALIZADO 2025'!N28*'PREVISTO 2026 REVISADO'!$U$4 -> 31.2455 | Q6: ='REALIZADO 2025'!O28*'PREVISTO 2026 REVISADO'!$U$4 -> 31.5172 | R6: =SUM(F6:Q6) -> 552.6217 | S6: =R6/12 -> 46.051808
C7: 2.1.11 Reuniões-treinamentos | F7: ='REALIZADO 2025'!D29*'PREVISTO 2026 REVISADO'!$U$4 -> 0 | G7: ='REALIZADO 2025'!E29*'PREVISTO 2026 REVISADO'!$U$4 -> 0 | H7: ='REALIZADO 2025'!F29*'PREVISTO 2026 REVISADO'!$U$4 -> 196.34505 | I7: ='REALIZADO 2025'!G29*'PREVISTO 2026 REVISADO'!$U$4 -> 0 | J7: ='REALIZADO 2025'!H29*'PREVISTO 2026 REVISADO'!$U$4 -> 0 | K7: ='REALIZADO 2025'!I29*'PREVISTO 2026 REVISADO'!$U$4 -> 0 | L7: ='REALIZADO 2025'!J29*'PREVISTO 2026 REVISADO'!$U$4 -> 415.91 | M7: ='REALIZADO 2025'!K29*'PREVISTO 2026 REVISADO'!$U$4 -> 176.5423 | ... Q7: ='REALIZADO 2025'!O29*'PREVISTO 2026 REVISADO'!$U$4 -> 0 | R7: =SUM(F7:Q7) -> 1213.4853 | S7: =R7/12 -> 101.12378
C8: 2.1.12 Certificado Digital | F8: ='REALIZADO 2025'!D30*'PREVISTO 2026 REVISADO'!$U$4 -> 0 | G8: ='REALIZADO 2025'!E30*'PREVISTO 2026 REVISADO'!$U$4 -> 0 | H8: ='REALIZADO 2025'!F30*'PREVISTO 2026 REVISADO'!$U$4 -> 0 | I8: ='REALIZADO 2025'!G30*'PREVISTO 2026 REVISADO'!$U$4 -> 0 | J8: ='REALIZADO 2025'!H30*'PREVISTO 2026 REVISADO'!$U$4 -> 187.65065 | K8: ='REALIZADO 2025'!I30*'PREVISTO 2026 REVISADO'!$U$4 -> 0 | L8: ='REALIZADO 2025'!J30*'PREVISTO 2026 REVISADO'!$U$4 -> 0 | M8: ='REALIZADO 2025'!K30*'PREVISTO 2026 REVISADO'!$U$4 -> 0 | ... Q8: ='REALIZADO 2025'!O30*'PREVISTO 2026 REVISADO'!$U$4 -> 0 | R8: =SUM(F8:Q8) -> 396.65065 | S8: =R8/12 -> 33.054221
C9: 2.1.14 Outros-não Previstos | F9: ='REALIZADO 2025'!D31*'PREVISTO 2026 REVISADO'!$U$4 -> 0 | G9: ='REALIZADO 2025'!E31*'PREVISTO 2026 REVISADO'!$U$4 -> 0 | H9: ='REALIZADO 2025'!F31*'PREVISTO 2026 REVISADO'!$U$4 -> 0 | I9: ='REALIZADO 2025'!G31*'PREVISTO 2026 REVISADO'!$U$4 -> 2612.5 | J9: ='REALIZADO 2025'!H31*'PREVISTO 2026 REVISADO'!$U$4 -> 0 | K9: ='REALIZADO 2025'!I31*'PREVISTO 2026 REVISADO'!$U$4 -> 0 | L9: ='REALIZADO 2025'!J31*'PREVISTO 2026 REVISADO'!$U$4 -> 0 | M9: ='REALIZADO 2025'!K31*'PREVISTO 2026 REVISADO'!$U$4 -> 0 | ... Q9: ='REALIZADO 2025'!O31*'PREVISTO 2026 REVISADO'!$U$4 -> 0 | R9: =SUM(F9:Q9) -> 2612.5 | S9: =R9/12 -> 217.70833
C10: 2.1.19 Alvará De Funcionamento | F10: ='REALIZADO 2025'!D34*'PREVISTO 2026 REVISADO'!$U$4 -> 0 | G10: ='REALIZADO 2025'!E34*'PREVISTO 2026 REVISADO'!$U$4 -> 0 | H10: ='REALIZADO 2025'!F34*'PREVISTO 2026 REVISADO'!$U$4 -> 0 | I10: ='REALIZADO 2025'!G34*'PREVISTO 2026 REVISADO'!$U$4 -> 0 | J10: ='REALIZADO 2025'!H34*'PREVISTO 2026 REVISADO'!$U$4 -> 0 | K10: ='REALIZADO 2025'!I34*'PREVISTO 2026 REVISADO'!$U$4 -> 621.4824 | L10: ='REALIZADO 2025'!J34*'PREVISTO 2026 REVISADO'!$U$4 -> 0 | M10: ='REALIZADO 2025'!K34*'PREVISTO 2026 REVISADO'!$U$4 -> 0 | ... Q10: ='REALIZADO 2025'!O34*'PREVISTO 2026 REVISADO'!$U$4 -> 0 | R10: =SUM(F10:Q10) -> 621.4824 | S10: =R10/12 -> 51.7902
C11: 2.1.2 Material De Expediente-correio | F11: ='REALIZADO 2025'!D35*'PREVISTO 2026 REVISADO'!$U$4 -> 372.17675 | G11: ='REALIZADO 2025'!E35*'PREVISTO 2026 REVISADO'!$U$4 -> 365.75 | H11: ='REALIZADO 2025'!F35*'PREVISTO 2026 REVISADO'!$U$4 -> 937.0515 | I11: ='REALIZADO 2025'!G35*'PREVISTO 2026 REVISADO'!$U$4 -> 510.43025 | J11: ='REALIZADO 2025'!H35*'PREVISTO 2026 REVISADO'!$U$4 -> 320.76275 | K11: ='REALIZADO 2025'!I35*'PREVISTO 2026 REVISADO'!$U$4 -> 403.37 | L11: ='REALIZADO 2025'!J35*'PREVISTO 2026 REVISADO'!$U$4 -> 1135.706 | M11: ='REALIZADO 2025'!K35*'PREVISTO 2026 REVISADO'!$U$4 -> 406.45275 | ... Q11: ='REALIZADO 2025'!O35*'PREVISTO 2026 REVISADO'!$U$4 -> 328.757 | R11: =SUM(F11:Q11) -> 7239.9167 | S11: =R11/12 -> 603.3264
C12: 2.1.21 Sistema De Reservas On-line | F12: ='REALIZADO 2025'!D36*'PREVISTO 2026 REVISADO'!$U$4 -> 522.5 | G12: ='REALIZADO 2025'!E36*'PREVISTO 2026 REVISADO'!$U$4 -> 0 | H12: ='REALIZADO 2025'!F36*'PREVISTO 2026 REVISADO'!$U$4 -> 522.5 | I12: ='REALIZADO 2025'!G36*'PREVISTO 2026 REVISADO'!$U$4 -> 522.5 | J12: ='REALIZADO 2025'!H36*'PREVISTO 2026 REVISADO'!$U$4 -> 522.5 | K12: ='REALIZADO 2025'!I36*'PREVISTO 2026 REVISADO'!$U$4 -> 522.5 | L12: ='REALIZADO 2025'!J36*'PREVISTO 2026 REVISADO'!$U$4 -> 0 | M12: ='REALIZADO 2025'!K36*'PREVISTO 2026 REVISADO'!$U$4 -> 522.5 | ... Q12: ='REALIZADO 2025'!O36*'PREVISTO 2026 REVISADO'!$U$4 -> 0 | R12: =SUM(F12:Q12) -> 4702.5 | S12: =R12/12 -> 391.875
C13: 2.1.22 Material Expediente- Impressões/Digitalizações/Encadernação/Envelopes | F13: ='REALIZADO 2025'!D37*'PREVISTO 2026 REVISADO'!$U$4 -> 0 | G13: ='REALIZADO 2025'!E37*'PREVISTO 2026 REVISADO'!$U$4 -> 0 | H13: ='REALIZADO 2025'!F37*'PREVISTO 2026 REVISADO'!$U$4 -> 0 | I13: ='REALIZADO 2025'!G37*'PREVISTO 2026 REVISADO'!$U$4 -> 0 | J13: ='REALIZADO 2025'!H37*'PREVISTO 2026 REVISADO'!$U$4 -> 0 | K13: ='REALIZADO 2025'!I37*'PREVISTO 2026 REVISADO'!$U$4 -> 0 | L13: ='REALIZADO 2025'!J37*'PREVISTO 2026 REVISADO'!$U$4 -> 0 | M13: ='REALIZADO 2025'!K37*'PREVISTO 2026 REVISADO'!$U$4 -> 0 | ... Q13: ='REALIZADO 2025'!O37*'PREVISTO 2026 REVISADO'!$U$4 -> 1418.4307 | R13: =SUM(F13:Q13) -> 1418.4307 | S13: =R13/12 -> 118.20256
C14: 2.1.3 Honorário Síndico | F14: =5043.17*$U$4 -> 5270.1127 | G14: =5043.17*$U$4 -> 5270.1127 | H14: =5043.17*$U$4 -> 5270.1127 | I14: =5043.17*$U$4 -> 5270.1127 | J14: =5043.17*$U$4 -> 5270.1127 | K14: =5043.17*$U$4 -> 5270.1127 | L14: =5043.17*$U$4 -> 5270.1127 | M14: =5043.17*$U$4 -> 5270.1127 | ... Q14: =5043.17*$U$4 -> 5270.1127 | R14: =SUM(F14:Q14) -> 63241.352 | S14: =R14/12 -> 5270.1127
C15: 2.1.4 Inss-ir-síndico | F15: =2570.4*$U$4 -> 2686.068 | G15: =2570.4*$U$4 -> 2686.068 | H15: =2570.4*$U$4 -> 2686.068 | I15: =2570.4*$U$4 -> 2686.068 | J15: =2570.4*$U$4 -> 2686.068 | K15: =2570.4*$U$4 -> 2686.068 | L15: =2570.4*$U$4 -> 2686.068 | M15: =2570.4*$U$4 -> 2686.068 | ... Q15: =2570.4*$U$4 -> 2686.068 | R15: =SUM(F15:Q15) -> 32232.816 | S15: =R15/12 -> 2686.068
C16: 2.1.5 Iptu | F16: ='REALIZADO 2025'!D40*'PREVISTO 2026 REVISADO'!$U$4 -> 0 | G16: ='REALIZADO 2025'!E40*'PREVISTO 2026 REVISADO'!$U$4 -> 0 | H16: ='REALIZADO 2025'!F40*'PREVISTO 2026 REVISADO'!$U$4 -> 68382.052 | I16: ='REALIZADO 2025'!G40*'PREVISTO 2026 REVISADO'!$U$4 -> 0 | J16: ='REALIZADO 2025'!H40*'PREVISTO 2026 REVISADO'!$U$4 -> 0 | K16: ='REALIZADO 2025'!I40*'PREVISTO 2026 REVISADO'!$U$4 -> 0 | L16: ='REALIZADO 2025'!J40*'PREVISTO 2026 REVISADO'!$U$4 -> 0 | M16: ='REALIZADO 2025'!K40*'PREVISTO 2026 REVISADO'!$U$4 -> 0 | ... Q16: ='REALIZADO 2025'!O40*'PREVISTO 2026 REVISADO'!$U$4 -> 0 | R16: =SUM(F16:Q16) -> 68382.052 | S16: =R16/12 -> 5698.5043
C17: 2.1.6 Taxa De Lixo | F17: ='REALIZADO 2025'!D41*'PREVISTO 2026 REVISADO'!$U$4 -> 0 | G17: ='REALIZADO 2025'!E41*'PREVISTO 2026 REVISADO'!$U$4 -> 0 | H17: ='REALIZADO 2025'!F41*'PREVISTO 2026 REVISADO'!$U$4 -> 5540.266 | I17: ='REALIZADO 2025'!G41*'PREVISTO 2026 REVISADO'!$U$4 -> 0 | J17: ='REALIZADO 2025'!H41*'PREVISTO 2026 REVISADO'!$U$4 -> 0 | K17: ='REALIZADO 2025'!I41*'PREVISTO 2026 REVISADO'!$U$4 -> 0 | L17: ='REALIZADO 2025'!J41*'PREVISTO 2026 REVISADO'!$U$4 -> 0 | M17: ='REALIZADO 2025'!K41*'PREVISTO 2026 REVISADO'!$U$4 -> 0 | ... Q17: ='REALIZADO 2025'!O41*'PREVISTO 2026 REVISADO'!$U$4 -> 0 | R17: =SUM(F17:Q17) -> 5540.266 | S17: =R17/12 -> 461.68884
C18: 2.1.60 Outros | F18: ='REALIZADO 2025'!D42*'PREVISTO 2026 REVISADO'!$U$4 -> 0 | G18: ='REALIZADO 2025'!E42*'PREVISTO 2026 REVISADO'!$U$4 -> 0 | H18: ='REALIZADO 2025'!F42*'PREVISTO 2026 REVISADO'!$U$4 -> 0 | I18: ='REALIZADO 2025'!G42*'PREVISTO 2026 REVISADO'!$U$4 -> 0 | J18: ='REALIZADO 2025'!H42*'PREVISTO 2026 REVISADO'!$U$4 -> 731.53135 | K18: ='REALIZADO 2025'!I42*'PREVISTO 2026 REVISADO'!$U$4 -> 0 | L18: ='REALIZADO 2025'!J42*'PREVISTO 2026 REVISADO'!$U$4 -> 0 | M18: ='REALIZADO 2025'!K42*'PREVISTO 2026 REVISADO'!$U$4 -> 0 | ... Q18: ='REALIZADO 2025'!O42*'PREVISTO 2026 REVISADO'!$U$4 -> 0 | R18: =SUM(F18:Q18) -> 731.53135 | S18: =R18/12 -> 60.960946
C19: 2.1.7 Seguro | F19: ='REALIZADO 2025'!D43*'PREVISTO 2026 REVISADO'!$U$4 -> 0 | G19: ='REALIZADO 2025'!E43*'PREVISTO 2026 REVISADO'!$U$4 -> 0 | H19: ='REALIZADO 2025'!F43*'PREVISTO 2026 REVISADO'!$U$4 -> 0 | I19: ='REALIZADO 2025'!G43*'PREVISTO 2026 REVISADO'!$U$4 -> 0 | J19: ='REALIZADO 2025'!H43*'PREVISTO 2026 REVISADO'!$U$4 -> 0 | K19: ='REALIZADO 2025'!I43*'PREVISTO 2026 REVISADO'!$U$4 -> 1386.6418 | L19: ='REALIZADO 2025'!J43*'PREVISTO 2026 REVISADO'!$U$4 -> 1386.6418 | M19: ='REALIZADO 2025'!K43*'PREVISTO 2026 REVISADO'!$U$4 -> 1386.6418 | ... Q19: ='REALIZADO 2025'!O43*'PREVISTO 2026 REVISADO'!$U$4 -> 0 | R19: =SUM(F19:Q19) -> 8319.9556 | S19: =R19/12 -> 693.32963
C20: 2.1.8 Cartório | F20: ='REALIZADO 2025'!D44*'PREVISTO 2026 REVISADO'!$U$4 -> 252.50335 | G20: ='REALIZADO 2025'!E44*'PREVISTO 2026 REVISADO'!$U$4 -> 62.073 | H20: ='REALIZADO 2025'!F44*'PREVISTO 2026 REVISADO'!$U$4 -> 281.2722 | I20: ='REALIZADO 2025'!G44*'PREVISTO 2026 REVISADO'!$U$4 -> 124.146 | J20: ='REALIZADO 2025'!H44*'PREVISTO 2026 REVISADO'!$U$4 -> 0 | K20: ='REALIZADO 2025'!I44*'PREVISTO 2026 REVISADO'!$U$4 -> 802.4346 | L20: ='REALIZADO 2025'!J44*'PREVISTO 2026 REVISADO'!$U$4 -> 754.37505 | M20: ='REALIZADO 2025'!K44*'PREVISTO 2026 REVISADO'!$U$4 -> 274.3752 | ... Q20: ='REALIZADO 2025'!O44*'PREVISTO 2026 REVISADO'!$U$4 -> 0 | R20: =SUM(F20:Q20) -> 2818.6576 | S20: =R20/12 -> 234.88813
C21: 2.1.9 Documentação Veículo / Multas e Infrações | F21: ='REALIZADO 2025'!D45*'PREVISTO 2026 REVISADO'!$U$4 -> 0 | G21: ='REALIZADO 2025'!E45*'PREVISTO 2026 REVISADO'!$U$4 -> 0 | H21: ='REALIZADO 2025'!F45*'PREVISTO 2026 REVISADO'!$U$4 -> 0 | I21: ='REALIZADO 2025'!G45*'PREVISTO 2026 REVISADO'!$U$4 -> 0 | J21: ='REALIZADO 2025'!H45*'PREVISTO 2026 REVISADO'!$U$4 -> 0 | K21: ='REALIZADO 2025'!I45*'PREVISTO 2026 REVISADO'!$U$4 -> 0 | L21: ='REALIZADO 2025'!J45*'PREVISTO 2026 REVISADO'!$U$4 -> 0 | M21: ='REALIZADO 2025'!K45*'PREVISTO 2026 REVISADO'!$U$4 -> 0 | ... Q21: ='REALIZADO 2025'!O45*'PREVISTO 2026 REVISADO'!$U$4 -> 0 | R21: =SUM(F21:Q21) -> 3262.6258 | S21: =R21/12 -> 271.88549
C22: 2.2 Colaboradores | F22: =SUM(F23:F37) -> 154479.97 | G22: =SUM(G23:G37) -> 112015.2 | H22: =SUM(H23:H37) -> 94533.512 | I22: =SUM(I23:I37) -> 129753.64 | J22: =SUM(J23:J37) -> 99742.99 | K22: =SUM(K23:K37) -> 125942.13 | L22: =SUM(L23:L37) -> 124648.07 | M22: =SUM(M23:M37) -> 100689.33 | ... R22: =SUM(R23:R37) -> 1483394.4 | S22: =R22/12 -> 123616.2 | T22: REAJUSTE | U22: 1.08 | V22: 0.08
C23: 2.2.1 Salários Líquidos | F23: ='REALIZADO 2025'!D47*'PREVISTO 2026 REVISADO'!$U$22 -> 52560.36 | G23: ='REALIZADO 2025'!E47*'PREVISTO 2026 REVISADO'!$U$22 -> 50335.56 | H23: ='REALIZADO 2025'!F47*'PREVISTO 2026 REVISADO'!$U$22 -> 47781.36 | I23: ='REALIZADO 2025'!G47*'PREVISTO 2026 REVISADO'!$U$22 -> 51606.72 | J23: ='REALIZADO 2025'!H47*'PREVISTO 2026 REVISADO'!$U$22 -> 47565.36 | K23: ='REALIZADO 2025'!I47*'PREVISTO 2026 REVISADO'!$U$22 -> 51570.432 | L23: ='REALIZADO 2025'!J47*'PREVISTO 2026 REVISADO'!$U$22 -> 52953.48 | M23: ='REALIZADO 2025'!K47*'PREVISTO 2026 REVISADO'!$U$22 -> 47341.8 | ... Q23: ='REALIZADO 2025'!O47*'PREVISTO 2026 REVISADO'!$U$22 -> 57690.36 | R23: =SUM(F23:Q23) -> 616611.1 | S23: =R23/12 -> 51384.258
C24: 2.2.10 Benefícios Saúde-cesta Básica-copa | F24: ='REALIZADO 2025'!D48*'PREVISTO 2026 REVISADO'!$U$22 -> 23252.497 | G24: ='REALIZADO 2025'!E48*'PREVISTO 2026 REVISADO'!$U$22 -> 15102.04 | H24: ='REALIZADO 2025'!F48*'PREVISTO 2026 REVISADO'!$U$22 -> 6936.1164 | I24: ='REALIZADO 2025'!G48*'PREVISTO 2026 REVISADO'!$U$22 -> 23643.932 | J24: ='REALIZADO 2025'!H48*'PREVISTO 2026 REVISADO'!$U$22 -> 16979.242 | K24: ='REALIZADO 2025'!I48*'PREVISTO 2026 REVISADO'!$U$22 -> 21597.602 | L24: ='REALIZADO 2025'!J48*'PREVISTO 2026 REVISADO'!$U$22 -> 16055.701 | M24: ='REALIZADO 2025'!K48*'PREVISTO 2026 REVISADO'!$U$22 -> 17160.498 | ... Q24: ='REALIZADO 2025'!O48*'PREVISTO 2026 REVISADO'!$U$22 -> 17840.444 | R24: =SUM(F24:Q24) -> 210724.09 | S24: =R24/12 -> 17560.341
C25: 2.2.11 Uniforme-epi | F25: ='REALIZADO 2025'!D49*'PREVISTO 2026 REVISADO'!$U$22 -> 77.652 | G25: ='REALIZADO 2025'!E49*'PREVISTO 2026 REVISADO'!$U$22 -> 847.4112 | H25: ='REALIZADO 2025'!F49*'PREVISTO 2026 REVISADO'!$U$22 -> 342.9108 | I25: ='REALIZADO 2025'!G49*'PREVISTO 2026 REVISADO'!$U$22 -> 528.444 | J25: ='REALIZADO 2025'!H49*'PREVISTO 2026 REVISADO'!$U$22 -> 1798.74 | K25: ='REALIZADO 2025'!I49*'PREVISTO 2026 REVISADO'!$U$22 -> 1893.78 | L25: ='REALIZADO 2025'!J49*'PREVISTO 2026 REVISADO'!$U$22 -> 539.784 | M25: ='REALIZADO 2025'!K49*'PREVISTO 2026 REVISADO'!$U$22 -> 0 | ... Q25: ='REALIZADO 2025'!O49*'PREVISTO 2026 REVISADO'!$U$22 -> 1808.298 | R25: 12000 | S25: =R25/12 -> 1000
C26: 2.2.12 Laudos Médicos-exames | F26: ='REALIZADO 2025'!D50*'PREVISTO 2026 REVISADO'!$U$22 -> 266.1444 | G26: ='REALIZADO 2025'!E50*'PREVISTO 2026 REVISADO'!$U$22 -> 263.25 | H26: ='REALIZADO 2025'!F50*'PREVISTO 2026 REVISADO'!$U$22 -> 291.5676 | I26: ='REALIZADO 2025'!G50*'PREVISTO 2026 REVISADO'!$U$22 -> 278.7804 | J26: ='REALIZADO 2025'!H50*'PREVISTO 2026 REVISADO'!$U$22 -> 235.6236 | K26: ='REALIZADO 2025'!I50*'PREVISTO 2026 REVISADO'!$U$22 -> 247.7088 | L26: ='REALIZADO 2025'!J50*'PREVISTO 2026 REVISADO'!$U$22 -> 248.4 | M26: ='REALIZADO 2025'!K50*'PREVISTO 2026 REVISADO'!$U$22 -> 248.4 | ... Q26: ='REALIZADO 2025'!O50*'PREVISTO 2026 REVISADO'!$U$22 -> 308.6208 | R26: =SUM(F26:Q26) -> 3452.004 | S26: =R26/12 -> 287.667
C27: 2.2.13 Cursos-treinamentos | F27: ='REALIZADO 2025'!D51*'PREVISTO 2026 REVISADO'!$U$22 -> 0 | G27: ='REALIZADO 2025'!E51*'PREVISTO 2026 REVISADO'!$U$22 -> 0 | H27: ='REALIZADO 2025'!F51*'PREVISTO 2026 REVISADO'!$U$22 -> 0 | I27: ='REALIZADO 2025'!G51*'PREVISTO 2026 REVISADO'!$U$22 -> 0 | J27: ='REALIZADO 2025'!H51*'PREVISTO 2026 REVISADO'!$U$22 -> 0 | K27: ='REALIZADO 2025'!I51*'PREVISTO 2026 REVISADO'!$U$22 -> 0 | L27: ='REALIZADO 2025'!J51*'PREVISTO 2026 REVISADO'!$U$22 -> 0 | M27: ='REALIZADO 2025'!K51*'PREVISTO 2026 REVISADO'!$U$22 -> 0 | ... Q27: ='REALIZADO 2025'!O51*'PREVISTO 2026 REVISADO'!$U$22 -> 51.0624 | R27: =SUM(F27:Q27) -> 2204.2584 | S27: =R27/12 -> 183.6882
C28: 2.2.14 Brindes-confraternizações | F28: ='REALIZADO 2025'!D52*'PREVISTO 2026 REVISADO'!$U$22 -> 3033.612 | G28: ='REALIZADO 2025'!E52*'PREVISTO 2026 REVISADO'!$U$22 -> 3616.272 | H28: ='REALIZADO 2025'!F52*'PREVISTO 2026 REVISADO'!$U$22 -> 1596.888 | I28: ='REALIZADO 2025'!G52*'PREVISTO 2026 REVISADO'!$U$22 -> 788.4 | J28: ='REALIZADO 2025'!H52*'PREVISTO 2026 REVISADO'!$U$22 -> 0 | K28: ='REALIZADO 2025'!I52*'PREVISTO 2026 REVISADO'!$U$22 -> 1690.0596 | L28: ='REALIZADO 2025'!J52*'PREVISTO 2026 REVISADO'!$U$22 -> 0 | M28: ='REALIZADO 2025'!K52*'PREVISTO 2026 REVISADO'!$U$22 -> 0 | ... Q28: ='REALIZADO 2025'!O52*'PREVISTO 2026 REVISADO'!$U$22 -> 0 | R28: =SUM(F28:Q28) -> 11296.422 | S28: =R28/12 -> 941.3685
C29: 2.2.15 Seguro De Vida | F29: ='REALIZADO 2025'!D53*'PREVISTO 2026 REVISADO'!$U$22 -> 319.5936 | G29: ='REALIZADO 2025'!E53*'PREVISTO 2026 REVISADO'!$U$22 -> 319.5936 | H29: ='REALIZADO 2025'!F53*'PREVISTO 2026 REVISADO'!$U$22 -> 319.5936 | I29: ='REALIZADO 2025'!G53*'PREVISTO 2026 REVISADO'!$U$22 -> 319.5936 | J29: ='REALIZADO 2025'!H53*'PREVISTO 2026 REVISADO'!$U$22 -> 332.802 | K29: ='REALIZADO 2025'!I53*'PREVISTO 2026 REVISADO'!$U$22 -> 332.802 | L29: ='REALIZADO 2025'!J53*'PREVISTO 2026 REVISADO'!$U$22 -> 332.802 | M29: ='REALIZADO 2025'!K53*'PREVISTO 2026 REVISADO'!$U$22 -> 332.802 | ... Q29: ='REALIZADO 2025'!O53*'PREVISTO 2026 REVISADO'!$U$22 -> 534.5352 | R29: =SUM(F29:Q29) -> 4344.2568 | S29: =R29/12 -> 362.0214
C30: 2.2.16 Contribuição Sindical Empregados | F30: ='REALIZADO 2025'!D54*'PREVISTO 2026 REVISADO'!$U$22 -> 324 | G30: ='REALIZADO 2025'!E54*'PREVISTO 2026 REVISADO'!$U$22 -> 324 | H30: ='REALIZADO 2025'!F54*'PREVISTO 2026 REVISADO'!$U$22 -> 367.2 | I30: ='REALIZADO 2025'!G54*'PREVISTO 2026 REVISADO'!$U$22 -> 345.6 | J30: ='REALIZADO 2025'!H54*'PREVISTO 2026 REVISADO'!$U$22 -> 345.6 | K30: ='REALIZADO 2025'!I54*'PREVISTO 2026 REVISADO'!$U$22 -> 324 | L30: ='REALIZADO 2025'!J54*'PREVISTO 2026 REVISADO'!$U$22 -> 302.4 | M30: ='REALIZADO 2025'!K54*'PREVISTO 2026 REVISADO'!$U$22 -> 324 | ... Q30: ='REALIZADO 2025'!O54*'PREVISTO 2026 REVISADO'!$U$22 -> 0 | R30: =SUM(F30:Q30) -> 3304.8 | S30: =R30/12 -> 275.4
C31: 2.2.17 Contribuição Sindical Patronal | F31: ='REALIZADO 2025'!D55*'PREVISTO 2026 REVISADO'!$U$22 -> 0 | G31: ='REALIZADO 2025'!E55*'PREVISTO 2026 REVISADO'!$U$22 -> 0 | H31: ='REALIZADO 2025'!F55*'PREVISTO 2026 REVISADO'!$U$22 -> 0 | I31: ='REALIZADO 2025'!G55*'PREVISTO 2026 REVISADO'!$U$22 -> 0 | J31: ='REALIZADO 2025'!H55*'PREVISTO 2026 REVISADO'!$U$22 -> 0 | K31: ='REALIZADO 2025'!I55*'PREVISTO 2026 REVISADO'!$U$22 -> 0 | L31: ='REALIZADO 2025'!J55*'PREVISTO 2026 REVISADO'!$U$22 -> 0 | M31: ='REALIZADO 2025'!K55*'PREVISTO 2026 REVISADO'!$U$22 -> 0 | ... Q31: ='REALIZADO 2025'!O55*'PREVISTO 2026 REVISADO'!$U$22 -> 367.2 | R31: =SUM(F31:Q31) -> 712.8 | S31: =R31/12 -> 59.4
C32: 2.2.20 Tributos Dctf-web | F32: ='REALIZADO 2025'!D57*'PREVISTO 2026 REVISADO'!$U$22 -> 26005.406 | G32: ='REALIZADO 2025'!E57*'PREVISTO 2026 REVISADO'!$U$22 -> 25600.212 | H32: ='REALIZADO 2025'!F57*'PREVISTO 2026 REVISADO'!$U$22 -> 24219.011 | I32: ='REALIZADO 2025'!G57*'PREVISTO 2026 REVISADO'!$U$22 -> 24259.932 | J32: ='REALIZADO 2025'!H57*'PREVISTO 2026 REVISADO'!$U$22 -> 26176.943 | K32: ='REALIZADO 2025'!I57*'PREVISTO 2026 REVISADO'!$U$22 -> 27497.815 | L32: ='REALIZADO 2025'!J57*'PREVISTO 2026 REVISADO'!$U$22 -> 29137.298 | M32: ='REALIZADO 2025'!K57*'PREVISTO 2026 REVISADO'!$U$22 -> 28422.446 | ... Q32: ='REALIZADO 2025'!O57*'PREVISTO 2026 REVISADO'!$U$22 -> 29389.878 | R32: =SUM(F32:Q32) -> 321580.7 | S32: =R32/12 -> 26798.392
C33: 2.2.3 Fgts | F33: ='REALIZADO 2025'!D58*'PREVISTO 2026 REVISADO'!$U$22 -> 5940.0108 | G33: ='REALIZADO 2025'!E58*'PREVISTO 2026 REVISADO'!$U$22 -> 6738.3576 | H33: ='REALIZADO 2025'!F58*'PREVISTO 2026 REVISADO'!$U$22 -> 4368.816 | I33: ='REALIZADO 2025'!G58*'PREVISTO 2026 REVISADO'!$U$22 -> 4458.0024 | J33: ='REALIZADO 2025'!H58*'PREVISTO 2026 REVISADO'!$U$22 -> 4821.5196 | K33: ='REALIZADO 2025'!I58*'PREVISTO 2026 REVISADO'!$U$22 -> 4989.3084 | L33: ='REALIZADO 2025'!J58*'PREVISTO 2026 REVISADO'!$U$22 -> 5267.2032 | M33: ='REALIZADO 2025'!K58*'PREVISTO 2026 REVISADO'!$U$22 -> 5605.5024 | ... Q33: ='REALIZADO 2025'!O58*'PREVISTO 2026 REVISADO'!$U$22 -> 6208.488 | R33: =SUM(F33:Q33) -> 65711.941 | S33: =R33/12 -> 5475.9951
C34: 2.2.6 Férias | F34: ='REALIZADO 2025'!D59*'PREVISTO 2026 REVISADO'!$U$22 -> 0 | G34: ='REALIZADO 2025'!E59*'PREVISTO 2026 REVISADO'!$U$22 -> 0 | H34: ='REALIZADO 2025'!F59*'PREVISTO 2026 REVISADO'!$U$22 -> 6453.5292 | I34: ='REALIZADO 2025'!G59*'PREVISTO 2026 REVISADO'!$U$22 -> 9554.8356 | J34: ='REALIZADO 2025'!H59*'PREVISTO 2026 REVISADO'!$U$22 -> 0 | K34: ='REALIZADO 2025'!I59*'PREVISTO 2026 REVISADO'!$U$22 -> 14145.57 | L34: ='REALIZADO 2025'!J59*'PREVISTO 2026 REVISADO'!$U$22 -> 18469.642 | M34: ='REALIZADO 2025'!K59*'PREVISTO 2026 REVISADO'!$U$22 -> 0 | ... Q34: ='REALIZADO 2025'!O59*'PREVISTO 2026 REVISADO'!$U$22 -> 0 | R34: =SUM(F34:Q34) -> 57366.209 | S34: =R34/12 -> 4780.5174
C35: 2.2.7 13 Salário | F35: ='REALIZADO 2025'!D60*'PREVISTO 2026 REVISADO'!$U$22 -> 41884.214 | G35: ='REALIZADO 2025'!E60*'PREVISTO 2026 REVISADO'!$U$22 -> 0 | H35: ='REALIZADO 2025'!F60*'PREVISTO 2026 REVISADO'!$U$22 -> 0 | I35: ='REALIZADO 2025'!G60*'PREVISTO 2026 REVISADO'!$U$22 -> 0 | J35: ='REALIZADO 2025'!H60*'PREVISTO 2026 REVISADO'!$U$22 -> 0 | K35: ='REALIZADO 2025'!I60*'PREVISTO 2026 REVISADO'!$U$22 -> 0 | L35: ='REALIZADO 2025'!J60*'PREVISTO 2026 REVISADO'!$U$22 -> 0 | M35: ='REALIZADO 2025'!K60*'PREVISTO 2026 REVISADO'!$U$22 -> 0 | ... Q35: ='REALIZADO 2025'!O60*'PREVISTO 2026 REVISADO'!$U$22 -> 20089.08 | R35: =SUM(F35:Q35) -> 71808.854 | S35: =R35/12 -> 5984.0712
C36: 2.2.8 Rescisões | F36: ='REALIZADO 2025'!D61*'PREVISTO 2026 REVISADO'!$U$22 -> 0 | G36: ='REALIZADO 2025'!E61*'PREVISTO 2026 REVISADO'!$U$22 -> 7352.1864 | H36: ='REALIZADO 2025'!F61*'PREVISTO 2026 REVISADO'!$U$22 -> 0 | I36: ='REALIZADO 2025'!G61*'PREVISTO 2026 REVISADO'!$U$22 -> 13862.48 | J36: ='REALIZADO 2025'!H61*'PREVISTO 2026 REVISADO'!$U$22 -> 0 | K36: ='REALIZADO 2025'!I61*'PREVISTO 2026 REVISADO'!$U$22 -> 0 | L36: ='REALIZADO 2025'!J61*'PREVISTO 2026 REVISADO'!$U$22 -> 0 | M36: ='REALIZADO 2025'!K61*'PREVISTO 2026 REVISADO'!$U$22 -> 0 | ... Q36: ='REALIZADO 2025'!O61*'PREVISTO 2026 REVISADO'!$U$22 -> 1015.2 | R36: 90000 | S36: =R36/12 -> 7500
C37: 2.2.9 Vale Transporte | F37: ='REALIZADO 2025'!D62*'PREVISTO 2026 REVISADO'!$U$22 -> 816.48 | G37: ='REALIZADO 2025'!E62*'PREVISTO 2026 REVISADO'!$U$22 -> 1516.32 | H37: ='REALIZADO 2025'!F62*'PREVISTO 2026 REVISADO'!$U$22 -> 1856.52 | I37: ='REALIZADO 2025'!G62*'PREVISTO 2026 REVISADO'!$U$22 -> 106.92 | J37: ='REALIZADO 2025'!H62*'PREVISTO 2026 REVISADO'!$U$22 -> 1487.16 | K37: ='REALIZADO 2025'!I62*'PREVISTO 2026 REVISADO'!$U$22 -> 1653.048 | L37: ='REALIZADO 2025'!J62*'PREVISTO 2026 REVISADO'!$U$22 -> 1341.36 | M37: ='REALIZADO 2025'!K62*'PREVISTO 2026 REVISADO'!$U$22 -> 1253.88 | ... Q37: ='REALIZADO 2025'!O62*'PREVISTO 2026 REVISADO'!$U$22 -> 0 | R37: =SUM(F37:Q37) -> 12277.008 | S37: =R37/12 -> 1023.084
C38: 2.3 Manutenção | F38: =F39+F55+F68+F72 -> 48895.278 | G38: =G39+G55+G68+G72 -> 40170.981 | H38: =H39+H55+H68+H72 -> 45046.554 | I38: =I39+I55+I68+I72 -> 48792.712 | J38: =J39+J55+J68+J72 -> 77235.741 | K38: =K39+K55+K68+K72 -> 75126.429 | L38: =L39+L55+L68+L72 -> 57768.373 | M38: =M39+M55+M68+M72 -> 45237.298 | ... R38: =R39+R55+R68+R72 -> 638498.62 | S38: =R38/12 -> 53208.219 | T38: REAJUSTE | U38: 1.045 | V38: 0.045
C39: 2.3.1 Areas De Lazer | F39: =SUM(F40:F48) -> 11772.991 | G39: =SUM(G40:G48) -> 6239.162 | H39: =SUM(H40:H48) -> 4612.3374 | I39: =SUM(I40:I48) -> 5200.2335 | J39: =SUM(J40:J48) -> 55340.149 | K39: =SUM(K40:K48) -> 52472.271 | L39: =SUM(L40:L48) -> 32692.501 | M39: =SUM(M40:M48) -> 16665.378 | ... Q39: =SUM(Q40:Q48) -> 24886.111 | R39: =SUM(R40:R54) -> 332522.31 | S39: =R39/12 -> 27710.192
C40: 2.3.1.1 Salão De Festas Bosque | F40: ='REALIZADO 2025'!D65*'PREVISTO 2026 REVISADO'!$U$38 -> 1550.686 | G40: ='REALIZADO 2025'!E65*'PREVISTO 2026 REVISADO'!$U$38 -> 470.25 | H40: ='REALIZADO 2025'!F65*'PREVISTO 2026 REVISADO'!$U$38 -> 1302.07 | I40: ='REALIZADO 2025'!G65*'PREVISTO 2026 REVISADO'!$U$38 -> 767.64655 | J40: ='REALIZADO 2025'!H65*'PREVISTO 2026 REVISADO'!$U$38 -> 8109.0955 | K40: ='REALIZADO 2025'!I65*'PREVISTO 2026 REVISADO'!$U$38 -> 9680.88 | L40: ='REALIZADO 2025'!J65*'PREVISTO 2026 REVISADO'!$U$38 -> 1657.37 | M40: ='REALIZADO 2025'!K65*'PREVISTO 2026 REVISADO'!$U$38 -> 5182.4685 | ... Q40: ='REALIZADO 2025'!O65*'PREVISTO 2026 REVISADO'!$U$38 -> 1478.9467 | R40: 63600 | S40: =R40/12 -> 5300
...

Sheet REALIZADO 2025
D1: Dezembro | E1: Janeiro | F1: Fevereiro | G1: Março | H1: Abril | I1: Maio | J1: Junho | K1: Julho | L1: Agosto | M1: Setembro | N1: Outubro | O1: Novembro | P1: Total | Q1: Média
A2: 1 Receitas | D2: =SUM(D3:D24) -> 290185.65 | E2: =SUM(E3:E24) -> 308732.3 | F2: =SUM(F3:F24) -> 313677.08 | G2: =SUM(G3:G24) -> 309911.84 | H2: =SUM(H3:H24) -> 316572.56 | I2: =SUM(I3:I24) -> 290740.15 | J2: =SUM(J3:J24) -> 318477.94 | K2: =SUM(K3:K24) -> 363077.67 | ... O2: =SUM(O3:O24) -> 341763.38 | P2: =SUM(D2:O2) -> 3896477.6 | Q2: =P2/12 -> 324706.47
A3: 1.1 Taxa Condominial | D3: 239580.04 | E3: 253005.09 | F3: 265582.35 | G3: 262254.65 | H3: 263648.06 | I3: 255243.67 | J3: 276285.49 | K3: 278926.44 | L3: 289938.72 | M3: 267854.46 | N3: 263900.09 | O3: 284892.08 | P3: =SUM(D3:O3) -> 3201111.1 | Q3: =P3/12 -> 266759.26
A4: 1.10 Rendimentos | D4: 8221.95 | E4: 12462.57 | F4: 8020.57 | G4: 9758.01 | H4: 14865.92 | I4: 131.75 | J4: 1440.44 | K4: 750.81 | L4: 6352.3 | M4: 19987.08 | N4: 6970.17 | O4: 4858.56 | P4: =SUM(D4:O4) -> 93820.13 | Q4: =P4/12 -> 7818.3442
A5: 1.11 Liberação Obra | D5: 0 | E5: 0 | F5: 0 | G5: 0 | H5: 0 | I5: 0 | J5: 0 | K5: 1379.6 | L5: 2950.48 | M5: 1379.6 | N5: 0 | O5: 0 | P5: =SUM(D5:O5) -> 5709.68 | Q5: =P5/12 -> 475.80667
A6: 1.12 Honorário Advocatício | D6: 0 | E6: 0 | F6: 0 | G6: 0 | H6: 0 | I6: 0 | J6: 1458.91 | K6: 0 | L6: 3358.15 | M6: 0 | N6: 0 | O6: 686.92 | P6: =SUM(D6:O6) -> 5503.98 | Q6: =P6/12 -> 458.665
A7: 1.13 Pagamentos a Menor | D7: 0 | E7: 0 | F7: 0 | G7: 0 | H7: -10.85 | I7: 0 | J7: 10.85 | K7: 0 | L7: 0 | M7: 0 | N7: 0 | O7: 0 | P7: =SUM(D7:O7) -> 0 | Q7: =P7/12 -> 0
A8: 1.17 Taxa Salão Bosque | D8: 525 | E8: 1050 | F8: 0 | G8: 1050 | H8: 1050 | I8: 0 | J8: 0 | K8: 1050 | L8: 525 | M8: 0 | N8: 0 | O8: 0 | P8: =SUM(D8:O8) -> 5250 | Q8: =P8/12 -> 437.5
A9: 1.18 Taxa Salão Piscina | D9: 1260 | E9: 1260 | F9: 3150 | G9: 1680 | H9: 1470 | I9: 1680 | J9: 420 | K9: 1680 | L9: 1218 | M9: 1890 | N9: 1470 | O9: 882 | P9: =SUM(D9:O9) -> 18060 | Q9: =P9/12 -> 1505
A10: 1.19 Taxa Salão Pub | D10: 1706.95 | E10: 2126.95 | F10: 0 | G10: 1916.95 | H10: 1496.95 | I10: 1050 | J10: 1890 | K10: 1050 | L10: 1680 | M10: 2520 | N10: 1470 | O10: 1470 | P10: =SUM(D10:O10) -> 18377.8 | Q10: =P10/12 -> 1531.4833
A11: 1.2 Fundo De Reserva | D11: 23926.35 | E11: 25269.43 | F11: 26519.07 | G11: 26186.3 | H11: 26325.65 | I11: 25485.2 | J11: 27589.36 | K11: 27853.49 | L11: 28954.69 | M11: 26746.27 | N11: 26277.64 | O11: 28063.87 | P11: =SUM(D11:O11) -> 319197.32 | Q11: =P11/12 -> 26599.777
A12: 1.20 Taxa Quiosque | D12: 150 | E12: 250 | F12: 150 | G12: 450 | H12: 200 | I12: 250 | J12: 200 | K12: 100 | L12: 100 | M12: 300 | N12: 150 | O12: 0 | P12: =SUM(D12:O12) -> 2300 | Q12: =P12/12 -> 191.66667
A13: 1.21 Taxa Campo Futebol | D13: 0 | E13: 0 | F13: 1800 | G13: 0 | H13: 800 | I13: 1700 | J13: 1900 | K13: 1800 | L13: 1400 | M13: 1400 | N13: 1200 | O13: 1200 | P13: =SUM(D13:O13) -> 13200 | Q13: =P13/12 -> 1100
A14: 1.23 Ressarcimento Utensílios-danos | D14: 317.67 | E14: 447.46 | F14: 419.33 | G14: 489.74 | H14: 439.72 | I14: 21.99 | J14: 111.24 | K14: 631.29 | L14: 196.05 | M14: 326.5 | N14: 57.39 | O14: 0 | P14: =SUM(D14:O14) -> 3458.38 | Q14: =P14/12 -> 288.19833
... A24: 1.9 Atualização Monetária | D24: 164.67 | E24: 211.09 | F24: 253.21 | G24: 64.91 | H24: 75.54 | I24: 0 | J24: 297.41 | K24: 23.96 | L24: 688.42 | M24: 50.05 | N24: 0 | O24: 49.94 | P24: =SUM(D24:O24) -> 1879.2 | Q24: =P24/12 -> 156.6
A25: TOTAL GERAL RECEITAS | D25: =D2 -> 290185.65 | E25: =E2 -> 308732.3 | F25: =F2 -> 313677.08 | G25: =G2 -> 309911.84 | H25: =H2 -> 316572.56 | I25: =I2 -> 290740.15 | J25: =J2 -> 318477.94 | K25: =K2 -> 363077.67 | ... O25: =O2 -> 341763.38 | P25: =SUM(D25:O25) -> 3896477.6 | Q25: =P25/12 -> 324706.47
A26: 2 Despesas | D26: =D27+D46+D63+D98+D108+D121 -> 308825.79 | E26: =E27+E46+E63+E98+E108+E121 -> 256130.14 | F26: =F27+F46+F63+F98+F108+F121 -> 318039.96 | G26: =G27+G46+G63+G98+G108+G121 -> 281471.1 | H26: =H27+H46+H63+H98+H108+H121 -> 308302.8 | I26: =I27+I46+I63+I98+I108+I121 -> 334819.06 | J26: =J27+J46+J63+J98+J108+J121 -> 504020.49 | K26: =K27+K46+K63+K98+K108+K121 -> 338176.55 | ... O26: =O27+O46+O63+O98+O108+O121 -> 310388.35 | P26: =SUM(D26:O26) -> 4191740.1 | Q26: =P26/12 -> 349311.67
A27: 2.1 Administrativas | D27: =SUM(D28:D45) -> 8428.59 | E27: =SUM(E28:E45) -> 7532.59 | F27: =SUM(F28:F45) -> 79958.24 | G27: =SUM(G28:G45) -> 12361.98 | H27: =SUM(H28:H45) -> 9069.81 | I27: =SUM(I28:I45) -> 10392.02 | J27: =SUM(J28:J45) -> 43773.35 | K27: =SUM(K28:K45) -> 9965.99 | ... O27: =SUM(O28:O45) -> 8987.82 | P27: =SUM(D27:O27) -> 224244.8 | Q27: =P27/12 -> 18687.067
A28: 2.1.1 Despesas Bancárias | D28: 553.58 | E28: 338.96 | F28: 78.99 | G28: 59.39 | H28: 97.22 | I28: 37.9 | J28: 32953.02 | K28: 31.9 | L28: 31.9 | M28: 32.9 | N28: 29.9 | O28: 30.16 | P28: =SUM(D28:O28) -> 34275.82 | Q28: =P28/12 -> 2856.3183
A29: 2.1.11 Reuniões-treinamentos | D29: 0 | E29: 0 | F29: 187.89 | G29: 0 | H29: 0 | I29: 0 | J29: 398 | K29: 168.94 | L29: 0 | M29: 0 | N29: 406.4 | O29: 0 | P29: =SUM(D29:O29) -> 1161.23 | Q29: =P29/12 -> 96.769167
A30: 2.1.12 Certificado Digital | D30: 0 | E30: 0 | F30: 0 | G30: 0 | H30: 179.57 | I30: 0 | J30: 0 | K30: 0 | L30: 0 | M30: 200 | N30: 0 | O30: 0 | P30: =SUM(D30:O30) -> 379.57 | Q30: =P30/12 -> 31.630833
A31: 2.1.14 Outros-não Previstos | D31: 0 | E31: 0 | F31: 0 | G31: 2500 | H31: 0 | I31: 0 | J31: 0 | K31: 0 | L31: 0 | M31: 0 | N31: 0 | O31: 0 | P31: =SUM(D31:O31) -> 2500 | Q31: =P31/12 -> 208.33333
A32: 2.1.16 Multa | D32: 0 | E32: 0 | F32: 0 | G32: 1408.64 | H32: 0 | I32: 0 | J32: 0 | K32: 0 | L32: 0 | M32: 0 | N32: 0 | O32: 0 | P32: =SUM(D32:O32) -> 1408.64 | Q32: =P32/12 -> 117.38667
A33: 2.1.17 Juros | D33: 0 | E33: 0 | F33: 0 | G33: 0 | H33: 0 | I33: 0 | J33: 0 | K33: 0 | L33: 0 | M33: 0 | N33: 1.65 | O33: 0 | P33: =SUM(D33:O33) -> 1.65 | Q33: =P33/12 -> 0.1375
A34: 2.1.19 Alvará De Funcionamento | D34: 0 | E34: 0 | F34: 0 | G34: 0 | H34: 0 | I34: 594.72 | J34: 0 | K34: 0 | L34: 0 | M34: 0 | N34: 0 | O34: 0 | P34: =SUM(D34:O34) -> 594.72 | Q34: =P34/12 -> 49.56
A35: 2.1.2 Material De Expediente-correio | D35: 356.15 | E35: 350 | F35: 896.7 | G35: 488.45 | H35: 306.95 | I35: 386 | J35: 1086.8 | K35: 388.95 | L35: 939.25 | M35: 880.2 | N35: 534.1 | O35: 314.6 | P35: =SUM(D35:O35) -> 6928.15 | Q35: =P35/12 -> 577.34583
A36: 2.1.21 Sistema De Reservas On-line | D36: 500 | E36: 0 | F36: 500 | G36: 500 | H36: 500 | I36: 500 | J36: 0 | K36: 500 | L36: 500 | M36: 500 | N36: 500 | O36: 0 | P36: =SUM(D36:O36) -> 4500 | Q36: =P36/12 -> 375
A37: 2.1.22 Material Expediente- Impressões/Digitalizações/Encadernação/Envelopes | D37: 0 | E37: 0 | F37: 0 | G37: 0 | H37: 0 | I37: 0 | J37: 0 | K37: 0 | L37: 0 | M37: 0 | N37: 0 | O37: 1357.35 | P37: =SUM(D37:O37) -> 1357.35 | Q37: =P37/12 -> 113.1125
A38: 2.1.3 Honorário Síndico | D38: 4540 | E38: 4540 | F38: 4814 | G38: 4814 | H38: 4814 | I38: 4814 | J38: 4827 | K38: 4827 | L38: 4826 | M38: 4827 | N38: 4827 | O38: 4826 | P38: =SUM(D38:O38) -> 57296 | Q38: =P38/12 -> 4774.6667
A39: 2.1.4 Inss-ir-síndico | D39: 2237.23 | E39: 2244.23 | F39: 2472.44 | G39: 2472.7 | H39: 2472.04 | I39: 1964.59 | J39: 2459.71 | K39: 2459.71 | L39: 2459.71 | M39: 2459.71 | N39: 2459.71 | O39: 2459.71 | P39: =SUM(D39:O39) -> 28621.49 | Q39: =P39/12 -> 2385.1242
... A45: 2.1.9 Documentação Veículo | D45: 0 | E45: 0 | F45: 0 | G45: 0 | H45: 0 | I45: 0 | J45: 0 | K45: 0 | L45: 3122.13 | M45: 0 | N45: 0 | O45: 0 | P45: =SUM(D45:O45) -> 3122.13 | Q45: =P45/12 -> 260.1775
A46: 2.2 Colaboradores | D46: =SUM(D47:D62) -> 143203.01 | E46: =SUM(E47:E62) -> 103883.78 | F46: =SUM(F47:F62) -> 87697.03 | G46: =SUM(G47:G62) -> 120308.26 | H46: =SUM(H47:H62) -> 92354.62 | I46: =SUM(I47:I62) -> 116613.08 | J46: =SUM(J47:J62) -> 115414.88 | K46: =SUM(K47:K62) -> 93230.86 | ... O46: =SUM(O47:O62) -> 125280.71 | P46: =SUM(D46:O46) -> 1310755.2 | Q46: =P46/12 -> 109229.6
A47: 2.2.1 Salários Líquidos | D47: 48667 | E47: 46607 | F47: 44242 | G47: 47784 | H47: 44042 | I47: 47750.4 | J47: 49031 | K47: 43835 | L47: 44045.8 | M47: 48132 | N47: 53383 | O47: 53417 | P47: =SUM(D47:O47) -> 570936.2 | Q47: =P47/12 -> 47578.017
A48: 2.2.10 Benefícios Saúde-cesta Básica-copa | D48: 21530.09 | E48: 13983.37 | F48: 6422.33 | G48: 21892.53 | H48: 15721.52 | I48: 19997.78 | J48: 14866.39 | K48: 15889.35 | L48: 15336.89 | M48: 16278.65 | N48: 16677.07 | O48: 16518.93 | P48: =SUM(D48:O48) -> 195114.9 | Q48: =P48/12 -> 16259.575
A49: 2.2.11 Uniforme-epi | D49: 71.9 | E49: 784.64 | F49: 317.51 | G49: 489.3 | H49: 1665.5 | I49: 1753.5 | J49: 499.8 | K49: 0 | L49: 370.91 | M49: 0 | N49: 1272.65 | O49: 1674.35 | P49: =SUM(D49:O49) -> 8900.06 | Q49: =P49/12 -> 741.67167
A50: 2.2.12 Laudos Médicos-exames | D50: 246.43 | E50: 243.75 | F50: 269.97 | G50: 258.13 | H50: 218.17 | I50: 229.36 | J50: 230 | K50: 230 | L50: 390.93 | M50: 293.19 | N50: 300.61 | O50: 285.76 | P50: =SUM(D50:O50) -> 3196.3 | Q50: =P50/12 -> 266.35833
A51: 2.2.13 Cursos-treinamentos | D51: 0 | E51: 0 | F51: 0 | G51: 0 | H51: 0 | I51: 0 | J51: 0 | K51: 0 | L51: 0 | M51: 0 | N51: 1993.7 | O51: 47.28 | P51: =SUM(D51:O51) -> 2040.98 | Q51: =P51/12 -> 170.08167
A52: 2.2.14 Brindes-confraternizações | D52: 2808.9 | E52: 3348.4 | F52: 1478.6 | G52: 730 | H52: 0 | I52: 1564.87 | J52: 0 | K52: 0 | L52: 0 | M52: 528.88 | N52: 0 | O52: 0 | P52: =SUM(D52:O52) -> 10459.65 | Q52: =P52/12 -> 871.6375
A53: 2.2.15 Seguro De Vida | D53: 295.92 | E53: 295.92 | F53: 295.92 | G53: 295.92 | H53: 308.15 | I53: 308.15 | J53: 308.15 | K53: 308.15 | L53: 308.15 | M53: 308.15 | N53: 494.94 | O53: 494.94 | P53: =SUM(D53:O53) -> 4022.46 | Q53: =P53/12 -> 335.205
A54: 2.2.16 Contribuição Sindical Empregados | D54: 300 | E54: 300 | F54: 340 | G54: 320 | H54: 320 | I54: 300 | J54: 280 | K54: 300 | L54: 300 | M54: 300 | N54: 0 | O54: 0 | P54: =SUM(D54:O54) -> 3060 | Q54: =P54/12 -> 255
...

Sheet PREVISTO 2026 REVISADO (2)
C1: Horiontal Praia Brava
C2: Previsão Orçamentária 2026
C3: Categorias | F3: Dezembro | G3: Janeiro | H3: Fevereiro | I3: Março | J3: Abril | K3: Maio | L3: Junho | M3: Julho | N3: Agosto | O3: Setembro | P3: Outubro | Q3: Novembro | R3: Total | S3: Média
C4: 2 Despesas | F4: =F5+F22+F38+F78+F86+#REF! -> #REF! | G4: =G5+G22+G38+G78+G86+#REF! -> #REF! | H4: =H5+H22+H38+H78+H86+#REF! -> #REF! | I4: =I5+I22+I38+I78+I86+#REF! -> #REF! | J4: =J5+J22+J38+J78+J86+#REF! -> #REF! | K4: =K5+K22+K38+K78+K86+#REF! -> #REF! | L4: =L5+L22+L38+L78+L86+#REF! -> #REF! | M4: =M5+M22+M38+M78+M86+#REF! -> #REF! | ... Q4: =Q5+Q22+Q38+Q78+Q86+#REF! -> #REF! | T4: REAJUSTE | U4: 1.045 | V4: 0.045
C5: 2.1 Administrativas | F5: =SUM(F6:F21) -> 9137.3607 | G5: =SUM(G6:G21) -> 8418.0037 | H5: =SUM(H6:H21) -> 83898.212 | I5: =SUM(I6:I21) -> 11787.819 | J5: =SUM(J6:J21) -> 9820.2203 | K5: =SUM(K6:K21) -> 11732.215 | L5: =SUM(L6:L21) -> 11683.814 | M5: =SUM(M6:M21) -> 10756.028 | ... R5: =SUM(R6:R21) -> 203286.84 | S5: =R5/12 -> 16940.57
C6: 2.1.1 Despesas Bancárias | F6: 34 | G6: 34 | H6: ='REALIZADO 2025'!F28*'PREVISTO 2026 REVISADO (2)'!$U$4 -> 82.54455 | I6: ='REALIZADO 2025'!G28*'PREVISTO 2026 REVISADO (2)'!$U$4 -> 62.06255 | J6: ='REALIZADO 2025'!H28*'PREVISTO 2026 REVISADO (2)'!$U$4 -> 101.5949 | K6: ='REALIZADO 2025'!I28*'PREVISTO 2026 REVISADO (2)'!$U$4 -> 39.6055 | L6: 35 | M6: ='REALIZADO 2025'!K28*'PREVISTO 2026 REVISADO (2)'!$U$4 -> 33.3355 | N6: ='REALIZADO 2025'!L28*'PREVISTO 2026 REVISADO (2)'!$U$4 -> 33.3355 | O6: ='REALIZADO 2025'!M28*'PREVISTO 2026 REVISADO (2)'!$U$4 -> 34.3805 | P6: ='REALIZADO 2025'!N28*'PREVISTO 2026 REVISADO (2)'!$U$4 -> 31.2455 | Q6: ='REALIZADO 2025'!O28*'PREVISTO 2026 REVISADO (2)'!$U$4 -> 31.5172 | R6: =SUM(F6:Q6) -> 552.6217 | S6: =R6/12 -> 46.051808
C7: 2.1.11 Reuniões-treinamentos | F7: ='REALIZADO 2025'!D29*'PREVISTO 2026 REVISADO (2)'!$U$4 -> 0 | G7: ='REALIZADO 2025'!E29*'PREVISTO 2026 REVISADO (2)'!$U$4 -> 0 | H7: ='REALIZADO 2025'!F29*'PREVISTO 2026 REVISADO (2)'!$U$4 -> 196.34505 | I7: ='REALIZADO 2025'!G29*'PREVISTO 2026 REVISADO (2)'!$U$4 -> 0 | J7: ='REALIZADO 2025'!H29*'PREVISTO 2026 REVISADO (2)'!$U$4 -> 0 | K7: ='REALIZADO 2025'!I29*'PREVISTO 2026 REVISADO (2)'!$U$4 -> 0 | L7: ='REALIZADO 2025'!J29*'PREVISTO 2026 REVISADO (2)'!$U$4 -> 415.91 | M7: ='REALIZADO 2025'!K29*'PREVISTO 2026 REVISADO (2)'!$U$4 -> 176.5423 | ... Q7: ='REALIZADO 2025'!O29*'PREVISTO 2026 REVISADO (2)'!$U$4 -> 0 | R7: =SUM(F7:Q7) -> 1213.4853 | S7: =R7/12 -> 101.12378
C8: 2.1.12 Certificado Digital | F8: ='REALIZADO 2025'!D30*'PREVISTO 2026 REVISADO (2)'!$U$4 -> 0 | G8: ='REALIZADO 2025'!E30*'PREVISTO 2026 REVISADO (2)'!$U$4 -> 0 | H8: ='REALIZADO 2025'!F30*'PREVISTO 2026 REVISADO (2)'!$U$4 -> 0 | I8: ='REALIZADO 2025'!G30*'PREVISTO 2026 REVISADO (2)'!$U$4 -> 0 | J8: ='REALIZADO 2025'!H30*'PREVISTO 2026 REVISADO (2)'!$U$4 -> 187.65065 | K8: ='REALIZADO 2025'!I30*'PREVISTO 2026 REVISADO (2)'!$U$4 -> 0 | L8: ='REALIZADO 2025'!J30*'PREVISTO 2026 REVISADO (2)'!$U$4 -> 0 | M8: ='REALIZADO 2025'!K30*'PREVISTO 2026 REVISADO (2)'!$U$4 -> 0 | ... Q8: ='REALIZADO 2025'!O30*'PREVISTO 2026 REVISADO (2)'!$U$4 -> 0 | R8: =SUM(F8:Q8) -> 396.65065 | S8: =R8/12 -> 33.054221
C9: 2.1.14 Outros-não Previstos | F9: ='REALIZADO 2025'!D31*'PREVISTO 2026 REVISADO (2)'!$U$4 -> 0 | G9: ='REALIZADO 2025'!E31*'PREVISTO 2026 REVISADO (2)'!$U$4 -> 0 | H9: ='REALIZADO 2025'!F31*'PREVISTO 2026 REVISADO (2)'!$U$4 -> 0 | I9: ='REALIZADO 2025'!G31*'PREVISTO 2026 REVISADO (2)'!$U$4 -> 2612.5 | J9: ='REALIZADO 2025'!H31*'PREVISTO 2026 REVISADO (2)'!$U$4 -> 0 | K9: ='REALIZADO 2025'!I31*'PREVISTO 2026 REVISADO (2)'!$U$4 -> 0 | L9: ='REALIZADO 2025'!J31*'PREVISTO 2026 REVISADO (2)'!$U$4 -> 0 | M9: ='REALIZADO 2025'!K31*'PREVISTO 2026 REVISADO (2)'!$U$4 -> 0 | ... Q9: ='REALIZADO 2025'!O31*'PREVISTO 2026 REVISADO (2)'!$U$4 -> 0 | R9: =SUM(F9:Q9) -> 2612.5 | S9: =R9/12 -> 217.70833
C10: 2.1.19 Alvará De Funcionamento | F10: ='REALIZADO 2025'!D34*'PREVISTO 2026 REVISADO (2)'!$U$4 -> 0 | G10: ='REALIZADO 2025'!E34*'PREVISTO 2026 REVISADO (2)'!$U$4 -> 0 | H10: ='REALIZADO 2025'!F34*'PREVISTO 2026 REVISADO (2)'!$U$4 -> 0 | I10: ='REALIZADO 2025'!G34*'PREVISTO 2026 REVISADO (2)'!$U$4 -> 0 | J10: ='REALIZADO 2025'!H34*'PREVISTO 2026 REVISADO (2)'!$U$4 -> 0 | K10: ='REALIZADO 2025'!I34*'PREVISTO 2026 REVISADO (2)'!$U$4 -> 621.4824 | L10: ='REALIZADO 2025'!J34*'PREVISTO 2026 REVISADO (2)'!$U$4 -> 0 | M10: ='REALIZADO 2025'!K34*'PREVISTO 2026 REVISADO (2)'!$U$4 -> 0 | ... Q10: ='REALIZADO 2025'!O34*'PREVISTO 2026 REVISADO (2)'!$U$4 -> 0 | R10: =SUM(F10:Q10) -> 621.4824 | S10: =R10/12 -> 51.7902
C11: 2.1.2 Material De Expediente-correio | F11: ='REALIZADO 2025'!D35*'PREVISTO 2026 REVISADO (2)'!$U$4 -> 372.17675 | G11: ='REALIZADO 2025'!E35*'PREVISTO 2026 REVISADO (2)'!$U$4 -> 365.75 | H11: ='REALIZADO 2025'!F35*'PREVISTO 2026 REVISADO (2)'!$U$4 -> 937.0515 | I11: ='REALIZADO 2025'!G35*'PREVISTO 2026 REVISADO (2)'!$U$4 -> 510.43025 | J11: ='REALIZADO 2025'!H35*'PREVISTO 2026 REVISADO (2)'!$U$4 -> 320.76275 | K11: ='REALIZADO 2025'!I35*'PREVISTO 2026 REVISADO (2)'!$U$4 -> 403.37 | L11: ='REALIZADO 2025'!J35*'PREVISTO 2026 REVISADO (2)'!$U$4 -> 1135.706 | M11: ='REALIZADO 2025'!K35*'PREVISTO 2026 REVISADO (2)'!$U$4 -> 406.45275 | ... Q11: ='REALIZADO 2025'!O35*'PREVISTO 2026 REVISADO (2)'!$U$4 -> 328.757 | R11: =SUM(F11:Q11) -> 7239.9167 | S11: =R11/12 -> 603.3264
C12: 2.1.21 Sistema De Reservas On-line | F12: ='REALIZADO 2025'!D36*'PREVISTO 2026 REVISADO (2)'!$U$4 -> 522.5 | G12: ='REALIZADO 2025'!E36*'PREVISTO 2026 REVISADO (2)'!$U$4 -> 0 | H12: ='REALIZADO 2025'!F36*'PREVISTO 2026 REVISADO (2)'!$U$4 -> 522.5 | I12: ='REALIZADO 2025'!G36*'PREVISTO 2026 REVISADO (2)'!$U$4 -> 522.5 | J12: ='REALIZADO 2025'!H36*'PREVISTO 2026 REVISADO (2)'!$U$4 -> 522.5 | K12: ='REALIZADO 2025'!I36*'PREVISTO 2026 REVISADO (2)'!$U$4 -> 522.5 | L12: ='REALIZADO 2025'!J36*'PREVISTO 2026 REVISADO (2)'!$U$4 -> 0 | M12: ='REALIZADO 2025'!K36*'PREVISTO 2026 REVISADO (2)'!$U$4 -> 522.5 | ... Q12: ='REALIZADO 2025'!O36*'PREVISTO 2026 REVISADO (2)'!$U$4 -> 0 | R12: =SUM(F12:Q12) -> 4702.5 | S12: =R12/12 -> 391.875
C13: 2.1.22 Material Expediente- Impressões/Digitalizações/Encadernação/Envelopes | F13: ='REALIZADO 2025'!D37*'PREVISTO 2026 REVISADO (2)'!$U$4 -> 0 | G13: ='REALIZADO 2025'!E37*'PREVISTO 2026 REVISADO (2)'!$U$4 -> 0 | H13: ='REALIZADO 2025'!F37*'PREVISTO 2026 REVISADO (2)'!$U$4 -> 0 | I13: ='REALIZADO 2025'!G37*'PREVISTO 2026 REVISADO (2)'!$U$4 -> 0 | J13: ='REALIZADO 2025'!H37*'PREVISTO 2026 REVISADO (2)'!$U$4 -> 0 | K13: ='REALIZADO 2025'!I37*'PREVISTO 2026 REVISADO (2)'!$U$4 -> 0 | L13: ='REALIZADO 2025'!J37*'PREVISTO 2026 REVISADO (2)'!$U$4 -> 0 | M13: ='REALIZADO 2025'!K37*'PREVISTO 2026 REVISADO (2)'!$U$4 -> 0 | ... Q13: ='REALIZADO 2025'!O37*'PREVISTO 2026 REVISADO (2)'!$U$4 -> 1418.4307 | R13: =SUM(F13:Q13) -> 1418.4307 | S13: =R13/12 -> 118.20256
C14: 2.1.3 Honorário Síndico | F14: =5043.17*$U$4 -> 5270.1127 | G14: =5043.17*$U$4 -> 5270.1127 | H14: =5043.17*$U$4 -> 5270.1127 | I14: =5043.17*$U$4 -> 5270.1127 | J14: =5043.17*$U$4 -> 5270.1127 | K14: =5043.17*$U$4 -> 5270.1127 | L14: =5043.17*$U$4 -> 5270.1127 | M14: =5043.17*$U$4 -> 5270.1127 | ... Q14: =5043.17*$U$4 -> 5270.1127 | R14: =SUM(F14:Q14) -> 63241.352 | S14: =R14/12 -> 5270.1127
C15: 2.1.4 Inss-ir-síndico | F15: =2570.4*$U$4 -> 2686.068 | G15: =2570.4*$U$4 -> 2686.068 | H15: =2570.4*$U$4 -> 2686.068 | I15: =2570.4*$U$4 -> 2686.068 | J15: =2570.4*$U$4 -> 2686.068 | K15: =2570.4*$U$4 -> 2686.068 | L15: =2570.4*$U$4 -> 2686.068 | M15: =2570.4*$U$4 -> 2686.068 | ... Q15: =2570.4*$U$4 -> 2686.068 | R15: =SUM(F15:Q15) -> 32232.816 | S15: =R15/12 -> 2686.068
C16: 2.1.5 Iptu | F16: ='REALIZADO 2025'!D40*'PREVISTO 2026 REVISADO (2)'!$U$4 -> 0 | G16: ='REALIZADO 2025'!E40*'PREVISTO 2026 REVISADO (2)'!$U$4 -> 0 | H16: ='REALIZADO 2025'!F40*'PREVISTO 2026 REVISADO (2)'!$U$4 -> 68382.052 | I16: ='REALIZADO 2025'!G40*'PREVISTO 2026 REVISADO (2)'!$U$4 -> 0 | J16: ='REALIZADO 2025'!H40*'PREVISTO 2026 REVISADO (2)'!$U$4 -> 0 | K16: ='REALIZADO 2025'!I40*'PREVISTO 2026 REVISADO (2)'!$U$4 -> 0 | L16: ='REALIZADO 2025'!J40*'PREVISTO 2026 REVISADO (2)'!$U$4 -> 0 | M16: ='REALIZADO 2025'!K40*'PREVISTO 2026 REVISADO (2)'!$U$4 -> 0 | ... Q16: ='REALIZADO 2025'!O40*'PREVISTO 2026 REVISADO (2)'!$U$4 -> 0 | R16: =SUM(F16:Q16) -> 68382.052 | S16: =R16/12 -> 5698.5043
C17: 2.1.6 Taxa De Lixo | F17: ='REALIZADO 2025'!D41*'PREVISTO 2026 REVISADO (2)'!$U$4 -> 0 | G17: ='REALIZADO 2025'!E41*'PREVISTO 2026 REVISADO (2)'!$U$4 -> 0 | H17: ='REALIZADO 2025'!F41*'PREVISTO 2026 REVISADO (2)'!$U$4 -> 5540.266 | I17: ='REALIZADO 2025'!G41*'PREVISTO 2026 REVISADO (2)'!$U$4 -> 0 | J17: ='REALIZADO 2025'!H41*'PREVISTO 2026 REVISADO (2)'!$U$4 -> 0 | K17: ='REALIZADO 2025'!I41*'PREVISTO 2026 REVISADO (2)'!$U$4 -> 0 | L17: ='REALIZADO 2025'!J41*'PREVISTO 2026 REVISADO (2)'!$U$4 -> 0 | M17: ='REALIZADO 2025'!K41*'PREVISTO 2026 REVISADO (2)'!$U$4 -> 0 | ... Q17: ='REALIZADO 2025'!O41*'PREVISTO 2026 REVISADO (2)'!$U$4 -> 0 | R17: =SUM(F17:Q17) -> 5540.266 | S17: =R17/12 -> 461.68884
C18: 2.1.60 Outros | F18: ='REALIZADO 2025'!D42*'PREVISTO 2026 REVISADO (2)'!$U$4 -> 0 | G18: ='REALIZADO 2025'!E42*'PREVISTO 2026 REVISADO (2)'!$U$4 -> 0 | H18: ='REALIZADO 2025'!F42*'PREVISTO 2026 REVISADO (2)'!$U$4 -> 0 | I18: ='REALIZADO 2025'!G42*'PREVISTO 2026 REVISADO (2)'!$U$4 -> 0 | J18: ='REALIZADO 2025'!H42*'PREVISTO 2026 REVISADO (2)'!$U$4 -> 731.53135 | K18: ='REALIZADO 2025'!I42*'PREVISTO 2026 REVISADO (2)'!$U$4 -> 0 | L18: ='REALIZADO 2025'!J42*'PREVISTO 2026 REVISADO (2)'!$U$4 -> 0 | M18: ='REALIZADO 2025'!K42*'PREVISTO 2026 REVISADO (2)'!$U$4 -> 0 | ... Q18: ='REALIZADO 2025'!O42*'PREVISTO 2026 REVISADO (2)'!$U$4 -> 0 | R18: =SUM(F18:Q18) -> 731.53135 | S18: =R18/12 -> 60.960946
C19: 2.1.7 Seguro | F19: ='REALIZADO 2025'!D43*'PREVISTO 2026 REVISADO (2)'!$U$4 -> 0 | G19: ='REALIZADO 2025'!E43*'PREVISTO 2026 REVISADO (2)'!$U$4 -> 0 | H19: ='REALIZADO 2025'!F43*'PREVISTO 2026 REVISADO (2)'!$U$4 -> 0 | I19: ='REALIZADO 2025'!G43*'PREVISTO 2026 REVISADO (2)'!$U$4 -> 0 | J19: ='REALIZADO 2025'!H43*'PREVISTO 2026 REVISADO (2)'!$U$4 -> 0 | K19: ='REALIZADO 2025'!I43*'PREVISTO 2026 REVISADO (2)'!$U$4 -> 1386.6418 | L19: ='REALIZADO 2025'!J43*'PREVISTO 2026 REVISADO (2)'!$U$4 -> 1386.6418 | M19: ='REALIZADO 2025'!K43*'PREVISTO 2026 REVISADO (2)'!$U$4 -> 1386.6418 | ... Q19: ='REALIZADO 2025'!O43*'PREVISTO 2026 REVISADO (2)'!$U$4 -> 0 | R19: =SUM(F19:Q19) -> 8319.9556 | S19: =R19/12 -> 693.32963
C20: 2.1.8 Cartório | F20: ='REALIZADO 2025'!D44*'PREVISTO 2026 REVISADO (2)'!$U$4 -> 252.50335 | G20: ='REALIZADO 2025'!E44*'PREVISTO 2026 REVISADO (2)'!$U$4 -> 62.073 | H20: ='REALIZADO 2025'!F44*'PREVISTO 2026 REVISADO (2)'!$U$4 -> 281.2722 | I20: ='REALIZADO 2025'!G44*'PREVISTO 2026 REVISADO (2)'!$U$4 -> 124.146 | J20: ='REALIZADO 2025'!H44*'PREVISTO 2026 REVISADO (2)'!$U$4 -> 0 | K20: ='REALIZADO 2025'!I44*'PREVISTO 2026 REVISADO (2)'!$U$4 -> 802.4346 | L20: ='REALIZADO 2025'!J44*'PREVISTO 2026 REVISADO (2)'!$U$4 -> 754.37505 | M20: ='REALIZADO 2025'!K44*'PREVISTO 2026 REVISADO (2)'!$U$4 -> 274.3752 | ... Q20: ='REALIZADO 2025'!O44*'PREVISTO 2026 REVISADO (2)'!$U$4 -> 0 | R20: =SUM(F20:Q20) -> 2818.6576 | S20: =R20/12 -> 234.88813
C21: 2.1.9 Documentação Veículo / Multas e Infrações | F21: ='REALIZADO 2025'!D45*'PREVISTO 2026 REVISADO (2)'!$U$4 -> 0 | G21: ='REALIZADO 2025'!E45*'PREVISTO 2026 REVISADO (2)'!$U$4 -> 0 | H21: ='REALIZADO 2025'!F45*'PREVISTO 2026 REVISADO (2)'!$U$4 -> 0 | I21: ='REALIZADO 2025'!G45*'PREVISTO 2026 REVISADO (2)'!$U$4 -> 0 | J21: ='REALIZADO 2025'!H45*'PREVISTO 2026 REVISADO (2)'!$U$4 -> 0 | K21: ='REALIZADO 2025'!I45*'PREVISTO 2026 REVISADO (2)'!$U$4 -> 0 | L21: ='REALIZADO 2025'!J45*'PREVISTO 2026 REVISADO (2)'!$U$4 -> 0 | M21: ='REALIZADO 2025'!K45*'PREVISTO 2026 REVISADO (2)'!$U$4 -> 0 | ... Q21: ='REALIZADO 2025'!O45*'PREVISTO 2026 REVISADO (2)'!$U$4 -> 0 | R21: =SUM(F21:Q21) -> 3262.6258 | S21: =R21/12 -> 271.88549
C22: 2.2 Colaboradores | F22: =SUM(F23:F37) -> 154479.97 | G22: =SUM(G23:G37) -> 112015.2 | H22: =SUM(H23:H37) -> 94533.512 | I22: =SUM(I23:I37) -> 129753.64 | J22: =SUM(J23:J37) -> 99742.99 | K22: =SUM(K23:K37) -> 125942.13 | L22: =SUM(L23:L37) -> 124648.07 | M22: =SUM(M23:M37) -> 100689.33 | ... R22: =SUM(R23:R37) -> 1483394.4 | S22: =R22/12 -> 123616.2 | T22: REAJUSTE | U22: 1.08 | V22: 0.08
C23: 2.2.1 Salários Líquidos | F23: ='REALIZADO 2025'!D47*'PREVISTO 2026 REVISADO (2)'!$U$22 -> 52560.36 | G23: ='REALIZADO 2025'!E47*'PREVISTO 2026 REVISADO (2)'!$U$22 -> 50335.56 | H23: ='REALIZADO 2025'!F47*'PREVISTO 2026 REVISADO (2)'!$U$22 -> 47781.36 | I23: ='REALIZADO 2025'!G47*'PREVISTO 2026 REVISADO (2)'!$U$22 -> 51606.72 | J23: ='REALIZADO 2025'!H47*'PREVISTO 2026 REVISADO (2)'!$U$22 -> 47565.36 | K23: ='REALIZADO 2025'!I47*'PREVISTO 2026 REVISADO (2)'!$U$22 -> 51570.432 | L23: ='REALIZADO 2025'!J47*'PREVISTO 2026 REVISADO (2)'!$U$22 -> 52953.48 | M23: ='REALIZADO 2025'!K47*'PREVISTO 2026 REVISADO (2)'!$U$22 -> 47341.8 | ... Q23: ='REALIZADO 2025'!O47*'PREVISTO 2026 REVISADO (2)'!$U$22 -> 57690.36 | R23: =SUM(F23:Q23) -> 616611.1 | S23: =R23/12 -> 51384.258
C24: 2.2.10 Benefícios Saúde-cesta Básica-copa | F24: ='REALIZADO 2025'!D48*'PREVISTO 2026 REVISADO (2)'!$U$22 -> 23252.497 | G24: ='REALIZADO 2025'!E48*'PREVISTO 2026 REVISADO (2)'!$U$22 -> 15102.04 | H24: ='REALIZADO 2025'!F48*'PREVISTO 2026 REVISADO (2)'!$U$22 -> 6936.1164 | I24: ='REALIZADO 2025'!G48*'PREVISTO 2026 REVISADO (2)'!$U$22 -> 23643.932 | J24: ='REALIZADO 2025'!H48*'PREVISTO 2026 REVISADO (2)'!$U$22 -> 16979.242 | K24: ='REALIZADO 2025'!I48*'PREVISTO 2026 REVISADO (2)'!$U$22 -> 21597.602 | L24: ='REALIZADO 2025'!J48*'PREVISTO 2026 REVISADO (2)'!$U$22 -> 16055.701 | M24: ='REALIZADO 2025'!K48*'PREVISTO 2026 REVISADO (2)'!$U$22 -> 17160.498 | ... Q24: ='REALIZADO 2025'!O48*'PREVISTO 2026 REVISADO (2)'!$U$22 -> 17840.444 | R24: =SUM(F24:Q24) -> 210724.09 | S24: =R24/12 -> 17560.341
C25: 2.2.11 Uniforme-epi | F25: ='REALIZADO 2025'!D49*'PREVISTO 2026 REVISADO (2)'!$U$22 -> 77.652 | G25: ='REALIZADO 2025'!E49*'PREVISTO 2026 REVISADO (2)'!$U$22 -> 847.4112 | H25: ='REALIZADO 2025'!F49*'PREVISTO 2026 REVISADO (2)'!$U$22 -> 342.9108 | I25: ='REALIZADO 2025'!G49*'PREVISTO 2026 REVISADO (2)'!$U$22 -> 528.444 | J25: ='REALIZADO 2025'!H49*'PREVISTO 2026 REVISADO (2)'!$U$22 -> 1798.74 | K25: ='REALIZADO 2025'!I49*'PREVISTO 2026 REVISADO (2)'!$U$22 -> 1893.78 | L25: ='REALIZADO 2025'!J49*'PREVISTO 2026 REVISADO (2)'!$U$22 -> 539.784 | M25: ='REALIZADO 2025'!K49*'PREVISTO 2026 REVISADO (2)'!$U$22 -> 0 | ... Q25: ='REALIZADO 2025'!O49*'PREVISTO 2026 REVISADO (2)'!$U$22 -> 1808.298 | R25: 12000 | S25: =R25/12 -> 1000
C26: 2.2.12 Laudos Médicos-exames | F26: ='REALIZADO 2025'!D50*'PREVISTO 2026 REVISADO (2)'!$U$22 -> 266.1444 | G26: ='REALIZADO 2025'!E50*'PREVISTO 2026 REVISADO (2)'!$U$22 -> 263.25 | H26: ='REALIZADO 2025'!F50*'PREVISTO 2026 REVISADO (2)'!$U$22 -> 291.5676 | I26: ='REALIZADO 2025'!G50*'PREVISTO 2026 REVISADO (2)'!$U$22 -> 278.7804 | J26: ='REALIZADO 2025'!H50*'PREVISTO 2026 REVISADO (2)'!$U$22 -> 235.6236 | K26: ='REALIZADO 2025'!I50*'PREVISTO 2026 REVISADO (2)'!$U$22 -> 247.7088 | L26: ='REALIZADO 2025'!J50*'PREVISTO 2026 REVISADO (2)'!$U$22 -> 248.4 | M26: ='REALIZADO 2025'!K50*'PREVISTO 2026 REVISADO (2)'!$U$22 -> 248.4 | ... Q26: ='REALIZADO 2025'!O50*'PREVISTO 2026 REVISADO (2)'!$U$22 -> 308.6208 | R26: =SUM(F26:Q26) -> 3452.004 | S26: =R26/12 -> 287.667
C27: 2.2.13 Cursos-treinamentos | F27: ='REALIZADO 2025'!D51*'PREVISTO 2026 REVISADO (2)'!$U$22 -> 0 | G27: ='REALIZADO 2025'!E51*'PREVISTO 2026 REVISADO (2)'!$U$22 -> 0 | H27: ='REALIZADO 2025'!F51*'PREVISTO 2026 REVISADO (2)'!$U$22 -> 0 | I27: ='REALIZADO 2025'!G51*'PREVISTO 2026 REVISADO (2)'!$U$22 -> 0 | J27: ='REALIZADO 2025'!H51*'PREVISTO 2026 REVISADO (2)'!$U$22 -> 0 | K27: ='REALIZADO 2025'!I51*'PREVISTO 2026 REVISADO (2)'!$U$22 -> 0 | L27: ='REALIZADO 2025'!J51*'PREVISTO 2026 REVISADO (2)'!$U$22 -> 0 | M27: ='REALIZADO 2025'!K51*'PREVISTO 2026 REVISADO (2)'!$U$22 -> 0 | ... Q27: ='REALIZADO 2025'!O51*'PREVISTO 2026 REVISADO (2)'!$U$22 -> 51.0624 | R27: =SUM(F27:Q27) -> 2204.2584 | S27: =R27/12 -> 183.6882
C28: 2.2.14 Brindes-confraternizações | F28: ='REALIZADO 2025'!D52*'PREVISTO 2026 REVISADO (2)'!$U$22 -> 3033.612 | G28: ='REALIZADO 2025'!E52*'PREVISTO 2026 REVISADO (2)'!$U$22 -> 3616.272 | H28: ='REALIZADO 2025'!F52*'PREVISTO 2026 REVISADO (2)'!$U$22 -> 1596.888 | I28: ='REALIZADO 2025'!G52*'PREVISTO 2026 REVISADO (2)'!$U$22 -> 788.4 | J28: ='REALIZADO 2025'!H52*'PREVISTO 2026 REVISADO (2)'!$U$22 -> 0 | K28: ='REALIZADO 2025'!I52*'PREVISTO 2026 REVISADO (2)'!$U$22 -> 1690.0596 | L28: ='REALIZADO 2025'!J52*'PREVISTO 2026 REVISADO (2)'!$U$22 -> 0 | M28: ='REALIZADO 2025'!K52*'PREVISTO 2026 REVISADO (2)'!$U$22 -> 0 | ... Q28: ='REALIZADO 2025'!O52*'PREVISTO 2026 REVISADO (2)'!$U$22 -> 0 | R28: =SUM(F28:Q28) -> 11296.422 | S28: =R28/12 -> 941.3685
C29: 2.2.15 Seguro De Vida | F29: ='REALIZADO 2025'!D53*'PREVISTO 2026 REVISADO (2)'!$U$22 -> 319.5936 | G29: ='REALIZADO 2025'!E53*'PREVISTO 2026 REVISADO (2)'!$U$22 -> 319.5936 | H29: ='REALIZADO 2025'!F53*'PREVISTO 2026 REVISADO (2)'!$U$22 -> 319.5936 | I29: ='REALIZADO 2025'!G53*'PREVISTO 2026 REVISADO (2)'!$U$22 -> 319.5936 | J29: ='REALIZADO 2025'!H53*'PREVISTO 2026 REVISADO (2)'!$U$22 -> 332.802 | K29: ='REALIZADO 2025'!I53*'PREVISTO 2026 REVISADO (2)'!$U$22 -> 332.802 | L29: ='REALIZADO 2025'!J53*'PREVISTO 2026 REVISADO (2)'!$U$22 -> 332.802 | M29: ='REALIZADO 2025'!K53*'PREVISTO 2026 REVISADO (2)'!$U$22 -> 332.802 | ... Q29: ='REALIZADO 2025'!O53*'PREVISTO 2026 REVISADO (2)'!$U$22 -> 534.5352 | R29: =SUM(F29:Q29) -> 4344.2568 | S29: =R29/12 -> 362.0214
C30: 2.2.16 Contribuição Sindical Empregados | F30: ='REALIZADO 2025'!D54*'PREVISTO 2026 REVISADO (2)'!$U$22 -> 324 | G30: ='REALIZADO 2025'!E54*'PREVISTO 2026 REVISADO (2)'!$U$22 -> 324 | H30: ='REALIZADO 2025'!F54*'PREVISTO 2026 REVISADO (2)'!$U$22 -> 367.2 | I30: ='REALIZADO 2025'!G54*'PREVISTO 2026 REVISADO (2)'!$U$22 -> 345.6 | J30: ='REALIZADO 2025'!H54*'PREVISTO 2026 REVISADO (2)'!$U$22 -> 345.6 | K30: ='REALIZADO 2025'!I54*'PREVISTO 2026 REVISADO (2)'!$U$22 -> 324 | L30: ='REALIZADO 2025'!J54*'PREVISTO 2026 REVISADO (2)'!$U$22 -> 302.4 | M30: ='REALIZADO 2025'!K54*'PREVISTO 2026 REVISADO (2)'!$U$22 -> 324 | ... Q30: ='REALIZADO 2025'!O54*'PREVISTO 2026 REVISADO (2)'!$U$22 -> 0 | R30: =SUM(F30:Q30) -> 3304.8 | S30: =R30/12 -> 275.4
C31: 2.2.17 Contribuição Sindical Patronal | F31: ='REALIZADO 2025'!D55*'PREVISTO 2026 REVISADO (2)'!$U$22 -> 0 | G31: ='REALIZADO 2025'!E55*'PREVISTO 2026 REVISADO (2)'!$U$22 -> 0 | H31: ='REALIZADO 2025'!F55*'PREVISTO 2026 REVISADO (2)'!$U$22 -> 0 | I31: ='REALIZADO 2025'!G55*'PREVISTO 2026 REVISADO (2)'!$U$22 -> 0 | J31: ='REALIZADO 2025'!H55*'PREVISTO 2026 REVISADO (2)'!$U$22 -> 0 | K31: ='REALIZADO 2025'!I55*'PREVISTO 2026 REVISADO (2)'!$U$22 -> 0 | L31: ='REALIZADO 2025'!J55*'PREVISTO 2026 REVISADO (2)'!$U$22 -> 0 | M31: ='REALIZADO 2025'!K55*'PREVISTO 2026 REVISADO (2)'!$U$22 -> 0 | ... Q31: ='REALIZADO 2025'!O55*'PREVISTO 2026 REVISADO (2)'!$U$22 -> 367.2 | R31: =SUM(F31:Q31) -> 712.8 | S31: =R31/12 -> 59.4
C32: 2.2.20 Tributos Dctf-web | F32: ='REALIZADO 2025'!D57*'PREVISTO 2026 REVISADO (2)'!$U$22 -> 26005.406 | G32: ='REALIZADO 2025'!E57*'PREVISTO 2026 REVISADO (2)'!$U$22 -> 25600.212 | H32: ='REALIZADO 2025'!F57*'PREVISTO 2026 REVISADO (2)'!$U$22 -> 24219.011 | I32: ='REALIZADO 2025'!G57*'PREVISTO 2026 REVISADO (2)'!$U$22 -> 24259.932 | J32: ='REALIZADO 2025'!H57*'PREVISTO 2026 REVISADO (2)'!$U$22 -> 26176.943 | K32: ='REALIZADO 2025'!I57*'PREVISTO 2026 REVISADO (2)'!$U$22 -> 27497.815 | L32: ='REALIZADO 2025'!J57*'PREVISTO 2026 REVISADO (2)'!$U$22 -> 29137.298 | M32: ='REALIZADO 2025'!K57*'PREVISTO 2026 REVISADO (2)'!$U$22 -> 28422.446 | ... Q32: ='REALIZADO 2025'!O57*'PREVISTO 2026 REVISADO (2)'!$U$22 -> 29389.878 | R32: =SUM(F32:Q32) -> 321580.7 | S32: =R32/12 -> 26798.392
C33: 2.2.3 Fgts | F33: ='REALIZADO 2025'!D58*'PREVISTO 2026 REVISADO (2)'!$U$22 -> 5940.0108 | G33: ='REALIZADO 2025'!E58*'PREVISTO 2026 REVISADO (2)'!$U$22 -> 6738.3576 | H33: ='REALIZADO 2025'!F58*'PREVISTO 2026 REVISADO (2)'!$U$22 -> 4368.816 | I33: ='REALIZADO 2025'!G58*'PREVISTO 2026 REVISADO (2)'!$U$22 -> 4458.0024 | J33: ='REALIZADO 2025'!H58*'PREVISTO 2026 REVISADO (2)'!$U$22 -> 4821.5196 | K33: ='REALIZADO 2025'!I58*'PREVISTO 2026 REVISADO (2)'!$U$22 -> 4989.3084 | L33: ='REALIZADO 2025'!J58*'PREVISTO 2026 REVISADO (2)'!$U$22 -> 5267.2032 | M33: ='REALIZADO 2025'!K58*'PREVISTO 2026 REVISADO (2)'!$U$22 -> 5605.5024 | ... Q33: ='REALIZADO 2025'!O58*'PREVISTO 2026 REVISADO (2)'!$U$22 -> 6208.488 | R33: =SUM(F33:Q33) -> 65711.941 | S33: =R33/12 -> 5475.9951
C34: 2.2.6 Férias | F34: ='REALIZADO 2025'!D59*'PREVISTO 2026 REVISADO (2)'!$U$22 -> 0 | G34: ='REALIZADO 2025'!E59*'PREVISTO 2026 REVISADO (2)'!$U$22 -> 0 | H34: ='REALIZADO 2025'!F59*'PREVISTO 2026 REVISADO (2)'!$U$22 -> 6453.5292 | I34: ='REALIZADO 2025'!G59*'PREVISTO 2026 REVISADO (2)'!$U$22 -> 9554.8356 | J34: ='REALIZADO 2025'!H59*'PREVISTO 2026 REVISADO (2)'!$U$22 -> 0 | K34: ='REALIZADO 2025'!I59*'PREVISTO 2026 REVISADO (2)'!$U$22 -> 14145.57 | L34: ='REALIZADO 2025'!J59*'PREVISTO 2026 REVISADO (2)'!$U$22 -> 18469.642 | M34: ='REALIZADO 2025'!K59*'PREVISTO 2026 REVISADO (2)'!$U$22 -> 0 | ... Q34: ='REALIZADO 2025'!O59*'PREVISTO 2026 REVISADO (2)'!$U$22 -> 0 | R34: =SUM(F34:Q34) -> 57366.209 | S34: =R34/12 -> 4780.5174
C35: 2.2.7 13 Salário | F35: ='REALIZADO 2025'!D60*'PREVISTO 2026 REVISADO (2)'!$U$22 -> 41884.214 | G35: ='REALIZADO 2025'!E60*'PREVISTO 2026 REVISADO (2)'!$U$22 -> 0 | H35: ='REALIZADO 2025'!F60*'PREVISTO 2026 REVISADO (2)'!$U$22 -> 0 | I35: ='REALIZADO 2025'!G60*'PREVISTO 2026 REVISADO (2)'!$U$22 -> 0 | J35: ='REALIZADO 2025'!H60*'PREVISTO 2026 REVISADO (2)'!$U$22 -> 0 | K35: ='REALIZADO 2025'!I60*'PREVISTO 2026 REVISADO (2)'!$U$22 -> 0 | L35: ='REALIZADO 2025'!J60*'PREVISTO 2026 REVISADO (2)'!$U$22 -> 0 | M35: ='REALIZADO 2025'!K60*'PREVISTO 2026 REVISADO (2)'!$U$22 -> 0 | ... Q35: ='REALIZADO 2025'!O60*'PREVISTO 2026 REVISADO (2)'!$U$22 -> 20089.08 | R35: =SUM(F35:Q35) -> 71808.854 | S35: =R35/12 -> 5984.0712
C36: 2.2.8 Rescisões | F36: ='REALIZADO 2025'!D61*'PREVISTO 2026 REVISADO (2)'!$U$22 -> 0 | G36: ='REALIZADO 2025'!E61*'PREVISTO 2026 REVISADO (2)'!$U$22 -> 7352.1864 | H36: ='REALIZADO 2025'!F61*'PREVISTO 2026 REVISADO (2)'!$U$22 -> 0 | I36: ='REALIZADO 2025'!G61*'PREVISTO 2026 REVISADO (2)'!$U$22 -> 13862.48 | J36: ='REALIZADO 2025'!H61*'PREVISTO 2026 REVISADO (2)'!$U$22 -> 0 | K36: ='REALIZADO 2025'!I61*'PREVISTO 2026 REVISADO (2)'!$U$22 -> 0 | L36: ='REALIZADO 2025'!J61*'PREVISTO 2026 REVISADO (2)'!$U$22 -> 0 | M36: ='REALIZADO 2025'!K61*'PREVISTO 2026 REVISADO (2)'!$U$22 -> 0 | ... Q36: ='REALIZADO 2025'!O61*'PREVISTO 2026 REVISADO (2)'!$U$22 -> 1015.2 | R36: 90000 | S36: =R36/12 -> 7500
C37: 2.2.9 Vale Transporte | F37: ='REALIZADO 2025'!D62*'PREVISTO 2026 REVISADO (2)'!$U$22 -> 816.48 | G37: ='REALIZADO 2025'!E62*'PREVISTO 2026 REVISADO (2)'!$U$22 -> 1516.32 | H37: ='REALIZADO 2025'!F62*'PREVISTO 2026 REVISADO (2)'!$U$22 -> 1856.52 | I37: ='REALIZADO 2025'!G62*'PREVISTO 2026 REVISADO (2)'!$U$22 -> 106.92 | J37: ='REALIZADO 2025'!H62*'PREVISTO 2026 REVISADO (2)'!$U$22 -> 1487.16 | K37: ='REALIZADO 2025'!I62*'PREVISTO 2026 REVISADO (2)'!$U$22 -> 1653.048 | L37: ='REALIZADO 2025'!J62*'PREVISTO 2026 REVISADO (2)'!$U$22 -> 1341.36 | M37: ='REALIZADO 2025'!K62*'PREVISTO 2026 REVISADO (2)'!$U$22 -> 1253.88 | ... Q37: ='REALIZADO 2025'!O62*'PREVISTO 2026 REVISADO (2)'!$U$22 -> 0 | R37: =SUM(F37:Q37) -> 12277.008 | S37: =R37/12 -> 1023.084
C38: 2.3 Manutenção | F38: =F39+F55+F68+F72 -> 48895.278 | G38: =G39+G55+G68+G72 -> 40170.981 | H38: =H39+H55+H68+H72 -> 45046.554 | I38: =I39+I55+I68+I72 -> 48792.712 | J38: =J39+J55+J68+J72 -> 77235.741 | K38: =K39+K55+K68+K72 -> 75126.429 | L38: =L39+L55+L68+L72 -> 57768.373 | M38: =M39+M55+M68+M72 -> 45237.298 | ... R38: =R39+R55+R68+R72 -> 638498.62 | S38: =R38/12 -> 53208.219 | T38: REAJUSTE | U38: 1.045 | V38: 0.045
C39: 2.3.1 Areas De Lazer | F39: =SUM(F40:F48) -> 11772.991 | G39: =SUM(G40:G48) -> 6239.162 | H39: =SUM(H40:H48) -> 4612.3374 | I39: =SUM(I40:I48) -> 5200.2335 | J39: =SUM(J40:J48) -> 55340.149 | K39: =SUM(K40:K48) -> 52472.271 | L39: =SUM(L40:L48) -> 32692.501 | M39: =SUM(M40:M48) -> 16665.378 | ... Q39: =SUM(Q40:Q48) -> 24886.111 | R39: =SUM(R40:R54) -> 332522.31 | S39: =R39/12 -> 27710.192
C40: 2.3.1.1 Salão De Festas Bosque | F40: ='REALIZADO 2025'!D65*'PREVISTO 2026 REVISADO (2)'!$U$38 -> 1550.686 | G40: ='REALIZADO 2025'!E65*'PREVISTO 2026 REVISADO (2)'!$U$38 -> 470.25 | H40: ='REALIZADO 2025'!F65*'PREVISTO 2026 REVISADO (2)'!$U$38 -> 1302.07 | I40: ='REALIZADO 2025'!G65*'PREVISTO 2026 REVISADO (2)'!$U$38 -> 767.64655 | J40: ='REALIZADO 2025'!H65*'PREVISTO 2026 REVISADO (2)'!$U$38 -> 8109.0955 | K40: ='REALIZADO 2025'!I65*'PREVISTO 2026 REVISADO (2)'!$U$38 -> 9680.88 | L40: ='REALIZADO 2025'!J65*'PREVISTO 2026 REVISADO (2)'!$U$38 -> 1657.37 | M40: ='REALIZADO 2025'!K65*'PREVISTO 2026 REVISADO (2)'!$U$38 -> 5182.4685 | ... Q40: ='REALIZADO 2025'!O65*'PREVISTO 2026 REVISADO (2)'!$U$38 -> 1478.9467 | R40: 63600 | S40: =R40/12 -> 5300
...

Sheet PREVISTO 2026
